Workbook

Sheet Trang tính1
A1: Dứt điểm (ATK) | B1: Dứt điểm, Sút xa, Chọn vị trí, Đánh đầu, Tạt | F1: Finisher | M1: ĐÓNG GÓP CỦA CHỈ SỐ GỐC VÀO OVR THEO VỊ TRÍ | Y1: CHIỀU CAO VÀ CÔNG THỨC JUM
A2: Phối hợp (DIS) | B2: Chuyền ngắn, Chuyền dài, Tầm Nhìn, Cầm bóng, Khéo léo | F2: PlayMaker | M2: Tự động theo trọng số nhóm B10:F20 và trọng số vị trí E24:J33. Mỗi cột phải bằng 100%; công thức bám đúng mẫu số /10 và /25 hiện tại. | Y2: JUM mới = ROUND((JUM gốc + Chiều cao cm - 100) / 2, 0). Ô chiều cao và JUM gốc là đầu vào có thể chỉnh sửa.
A3: Đột biến (CRE) | B3: Rê bóng, Cầm bóng, Khéo léo, Tầm Nhìn, Quyết đoán | F3: Maverick | M3: Chỉ số gốc | N3: =$D24 -> ST | O3: =$D25 -> CF | P3: =$D26 -> WF | Q3: =$D27 -> AM | R3: =$D28 -> WM | S3: =$D29 -> CM | T3: =$D30 -> PV | U3: =$D31 -> WB | V3: =$D32 -> FB | W3: =$D33 -> CB | Y3: Sheet | Z3: Cầu thủ | AA3: Chiều cao (cm) | AB3: JUM gốc | AC3: JUM mới | AD3: Thay đổi | AE3: Nguồn/ghi chú
A4: Thể chất (PHY) | B4: Tốc độ, tăng tốc, thể lực, sức mạnh, bật nhảy | F4: Beast | M4: =$A24 -> FIN | N4: =IFERROR((SUMIF($B$9:$F$9,$M4,$B$10:$F$10)*INDEX($E$24:$J$33,MATCH(N$3,$D$24:$D$33,0),MATCH($A$10,$E$23:$J$23,0))+SUMIF($B$11:$F$11,$M4,$B$12:$F$12)*INDEX($E$24:$J$33,MATCH(N$3,$D$24:$D$33,0),MATCH($A$12,$E$23:$J$23,0))+SUMIF($B$13:$F$13,$M4,$B$14:$F$14)*INDEX($E$24:$J$33,MATCH(N$3,$D$24:$D$33,0),MATCH($A$14,$E$23:$J$23,0))+SUMIF($B$15:$F$15,$M4,$B$16:$F$16)*INDEX($E$24:$J$33,MATCH(N$3,$D$24:$D$33,0),MATCH($A$16,$E$23:$J$23,0))+SUMIF($B$17:$F$17,$M4,$B$18:$F$18)*INDEX($E$24:$J$33,MATCH(N$3,$D$24:$D$33,0),MATCH($A$18,$E$23:$J$23,0))+SUMIF($B$19:$F$19,$M4,$B$20:$F$20)*INDEX($E$24:$J$33,MATCH(N$3,$D$24:$D$33,0),MATCH($A$20,$E$23:$J$23,0)))/250,0) -> 0.128 | O4: =IFERROR((SUMIF($B$9:$F$9,$M4,$B$10:$F$10)*INDEX($E$24:$J$33,MATCH(O$3,$D$24:$D$33,0),MATCH($A$10,$E$23:$J$23,0))+SUMIF($B$11:$F$11,$M4,$B$12:$F$12)*INDEX($E$24:$J$33,MATCH(O$3,$D$24:$D$33,0),MATCH($A$12,$E$23:$J$23,0))+SUMIF($B$13:$F$13,$M4,$B$14:$F$14)*INDEX($E$24:$J$33,MATCH(O$3,$D$24:$D$33,0),MATCH($A$14,$E$23:$J$23,0))+SUMIF($B$15:$F$15,$M4,$B$16:$F$16)*INDEX($E$24:$J$33,MATCH(O$3,$D$24:$D$33,0),MATCH($A$16,$E$23:$J$23,0))+SUMIF($B$17:$F$17,$M4,$B$18:$F$18)*INDEX($E$24:$J$33,MATCH(O$3,$D$24:$D$33,0),MATCH($A$18,$E$23:$J$23,0))+SUMIF($B$19:$F$19,$M4,$B$20:$F$20)*INDEX($E$24:$J$33,MATCH(O$3,$D$24:$D$33,0),MATCH($A$20,$E$23:$J$23,0)))/250,0) -> 0.096 | P4: =IFERROR((SUMIF($B$9:$F$9,$M4,$B$10:$F$10)*INDEX($E$24:$J$33,MATCH(P$3,$D$24:$D$33,0),MATCH($A$10,$E$23:$J$23,0))+SUMIF($B$11:$F$11,$M4,$B$12:$F$12)*INDEX($E$24:$J$33,MATCH(P$3,$D$24:$D$33,0),MATCH($A$12,$E$23:$J$23,0))+SUMIF($B$13:$F$13,$M4,$B$14:$F$14)*INDEX($E$24:$J$33,MATCH(P$3,$D$24:$D$33,0),MATCH($A$14,$E$23:$J$23,0))+SUMIF($B$15:$F$15,$M4,$B$16:$F$16)*INDEX($E$24:$J$33,MATCH(P$3,$D$24:$D$33,0),MATCH($A$16,$E$23:$J$23,0))+SUMIF($B$17:$F$17,$M4,$B$18:$F$18)*INDEX($E$24:$J$33,MATCH(P$3,$D$24:$D$33,0),MATCH($A$18,$E$23:$J$23,0))+SUMIF($B$19:$F$19,$M4,$B$20:$F$20)*INDEX($E$24:$J$33,MATCH(P$3,$D$24:$D$33,0),MATCH($A$20,$E$23:$J$23,0)))/250,0) -> 0.096 | Q4: =IFERROR((SUMIF($B$9:$F$9,$M4,$B$10:$F$10)*INDEX($E$24:$J$33,MATCH(Q$3,$D$24:$D$33,0),MATCH($A$10,$E$23:$J$23,0))+SUMIF($B$11:$F$11,$M4,$B$12:$F$12)*INDEX($E$24:$J$33,MATCH(Q$3,$D$24:$D$33,0),MATCH($A$12,$E$23:$J$23,0))+SUMIF($B$13:$F$13,$M4,$B$14:$F$14)*INDEX($E$24:$J$33,MATCH(Q$3,$D$24:$D$33,0),MATCH($A$14,$E$23:$J$23,0))+SUMIF($B$15:$F$15,$M4,$B$16:$F$16)*INDEX($E$24:$J$33,MATCH(Q$3,$D$24:$D$33,0),MATCH($A$16,$E$23:$J$23,0))+SUMIF($B$17:$F$17,$M4,$B$18:$F$18)*INDEX($E$24:$J$33,MATCH(Q$3,$D$24:$D$33,0),MATCH($A$18,$E$23:$J$23,0))+SUMIF($B$19:$F$19,$M4,$B$20:$F$20)*INDEX($E$24:$J$33,MATCH(Q$3,$D$24:$D$33,0),MATCH($A$20,$E$23:$J$23,0)))/250,0) -> 0.064 | R4: =IFERROR((SUMIF($B$9:$F$9,$M4,$B$10:$F$10)*INDEX($E$24:$J$33,MATCH(R$3,$D$24:$D$33,0),MATCH($A$10,$E$23:$J$23,0))+SUMIF($B$11:$F$11,$M4,$B$12:$F$12)*INDEX($E$24:$J$33,MATCH(R$3,$D$24:$D$33,0),MATCH($A$12,$E$23:$J$23,0))+SUMIF($B$13:$F$13,$M4,$B$14:$F$14)*INDEX($E$24:$J$33,MATCH(R$3,$D$24:$D$33,0),MATCH($A$14,$E$23:$J$23,0))+SUMIF($B$15:$F$15,$M4,$B$16:$F$16)*INDEX($E$24:$J$33,MATCH(R$3,$D$24:$D$33,0),MATCH($A$16,$E$23:$J$23,0))+SUMIF($B$17:$F$17,$M4,$B$18:$F$18)*INDEX($E$24:$J$33,MATCH(R$3,$D$24:$D$33,0),MATCH($A$18,$E$23:$J$23,0))+SUMIF($B$19:$F$19,$M4,$B$20:$F$20)*INDEX($E$24:$J$33,MATCH(R$3,$D$24:$D$33,0),MATCH($A$20,$E$23:$J$23,0)))/250,0) -> 0.048 | S4: =IFERROR((SUMIF($B$9:$F$9,$M4,$B$10:$F$10)*INDEX($E$24:$J$33,MATCH(S$3,$D$24:$D$33,0),MATCH($A$10,$E$23:$J$23,0))+SUMIF($B$11:$F$11,$M4,$B$12:$F$12)*INDEX($E$24:$J$33,MATCH(S$3,$D$24:$D$33,0),MATCH($A$12,$E$23:$J$23,0))+SUMIF($B$13:$F$13,$M4,$B$14:$F$14)*INDEX($E$24:$J$33,MATCH(S$3,$D$24:$D$33,0),MATCH($A$14,$E$23:$J$23,0))+SUMIF($B$15:$F$15,$M4,$B$16:$F$16)*INDEX($E$24:$J$33,MATCH(S$3,$D$24:$D$33,0),MATCH($A$16,$E$23:$J$23,0))+SUMIF($B$17:$F$17,$M4,$B$18:$F$18)*INDEX($E$24:$J$33,MATCH(S$3,$D$24:$D$33,0),MATCH($A$18,$E$23:$J$23,0))+SUMIF($B$19:$F$19,$M4,$B$20:$F$20)*INDEX($E$24:$J$33,MATCH(S$3,$D$24:$D$33,0),MATCH($A$20,$E$23:$J$23,0)))/250,0) -> 0.032 | T4: =IFERROR((SUMIF($B$9:$F$9,$M4,$B$10:$F$10)*INDEX($E$24:$J$33,MATCH(T$3,$D$24:$D$33,0),MATCH($A$10,$E$23:$J$23,0))+SUMIF($B$11:$F$11,$M4,$B$12:$F$12)*INDEX($E$24:$J$33,MATCH(T$3,$D$24:$D$33,0),MATCH($A$12,$E$23:$J$23,0))+SUMIF($B$13:$F$13,$M4,$B$14:$F$14)*INDEX($E$24:$J$33,MATCH(T$3,$D$24:$D$33,0),MATCH($A$14,$E$23:$J$23,0))+SUMIF($B$15:$F$15,$M4,$B$16:$F$16)*INDEX($E$24:$J$33,MATCH(T$3,$D$24:$D$33,0),MATCH($A$16,$E$23:$J$23,0))+SUMIF($B$17:$F$17,$M4,$B$18:$F$18)*INDEX($E$24:$J$33,MATCH(T$3,$D$24:$D$33,0),MATCH($A$18,$E$23:$J$23,0))+SUMIF($B$19:$F$19,$M4,$B$20:$F$20)*INDEX($E$24:$J$33,MATCH(T$3,$D$24:$D$33,0),MATCH($A$20,$E$23:$J$23,0)))/250,0) -> 0.016 | U4: =IFERROR((SUMIF($B$9:$F$9,$M4,$B$10:$F$10)*INDEX($E$24:$J$33,MATCH(U$3,$D$24:$D$33,0),MATCH($A$10,$E$23:$J$23,0))+SUMIF($B$11:$F$11,$M4,$B$12:$F$12)*INDEX($E$24:$J$33,MATCH(U$3,$D$24:$D$33,0),MATCH($A$12,$E$23:$J$23,0))+SUMIF($B$13:$F$13,$M4,$B$14:$F$14)*INDEX($E$24:$J$33,MATCH(U$3,$D$24:$D$33,0),MATCH($A$14,$E$23:$J$23,0))+SUMIF($B$15:$F$15,$M4,$B$16:$F$16)*INDEX($E$24:$J$33,MATCH(U$3,$D$24:$D$33,0),MATCH($A$16,$E$23:$J$23,0))+SUMIF($B$17:$F$17,$M4,$B$18:$F$18)*INDEX($E$24:$J$33,MATCH(U$3,$D$24:$D$33,0),MATCH($A$18,$E$23:$J$23,0))+SUMIF($B$19:$F$19,$M4,$B$20:$F$20)*INDEX($E$24:$J$33,MATCH(U$3,$D$24:$D$33,0),MATCH($A$20,$E$23:$J$23,0)))/250,0) -> 0.032 | ... W4: =IFERROR((SUMIF($B$9:$F$9,$M4,$B$10:$F$10)*INDEX($E$24:$J$33,MATCH(W$3,$D$24:$D$33,0),MATCH($A$10,$E$23:$J$23,0))+SUMIF($B$11:$F$11,$M4,$B$12:$F$12)*INDEX($E$24:$J$33,MATCH(W$3,$D$24:$D$33,0),MATCH($A$12,$E$23:$J$23,0))+SUMIF($B$13:$F$13,$M4,$B$14:$F$14)*INDEX($E$24:$J$33,MATCH(W$3,$D$24:$D$33,0),MATCH($A$14,$E$23:$J$23,0))+SUMIF($B$15:$F$15,$M4,$B$16:$F$16)*INDEX($E$24:$J$33,MATCH(W$3,$D$24:$D$33,0),MATCH($A$16,$E$23:$J$23,0))+SUMIF($B$17:$F$17,$M4,$B$18:$F$18)*INDEX($E$24:$J$33,MATCH(W$3,$D$24:$D$33,0),MATCH($A$18,$E$23:$J$23,0))+SUMIF($B$19:$F$19,$M4,$B$20:$F$20)*INDEX($E$24:$J$33,MATCH(W$3,$D$24:$D$33,0),MATCH($A$20,$E$23:$J$23,0)))/250,0) -> 0.016 | Y4: Messi Icon | Z4: LIONEL MESSI | AA4: 170 | AB4: 70 | AC4: =ROUND((AB4+AA4-100)/2,0) -> 70 | AD4: =AC4-AB4 -> 0 | AE4: Wikidata P2048 và hồ sơ CLB/giải đấu; có thể hiệu chỉnh
A5: Tâm lý (MEN) | B5: Bình tĩnh, Quyết đoán, Chọn vị trí, Tầm nhìn, Quyết định | F5: Solid Mental | M5: =$A25 -> LSH | N5: =IFERROR((SUMIF($B$9:$F$9,$M5,$B$10:$F$10)*INDEX($E$24:$J$33,MATCH(N$3,$D$24:$D$33,0),MATCH($A$10,$E$23:$J$23,0))+SUMIF($B$11:$F$11,$M5,$B$12:$F$12)*INDEX($E$24:$J$33,MATCH(N$3,$D$24:$D$33,0),MATCH($A$12,$E$23:$J$23,0))+SUMIF($B$13:$F$13,$M5,$B$14:$F$14)*INDEX($E$24:$J$33,MATCH(N$3,$D$24:$D$33,0),MATCH($A$14,$E$23:$J$23,0))+SUMIF($B$15:$F$15,$M5,$B$16:$F$16)*INDEX($E$24:$J$33,MATCH(N$3,$D$24:$D$33,0),MATCH($A$16,$E$23:$J$23,0))+SUMIF($B$17:$F$17,$M5,$B$18:$F$18)*INDEX($E$24:$J$33,MATCH(N$3,$D$24:$D$33,0),MATCH($A$18,$E$23:$J$23,0))+SUMIF($B$19:$F$19,$M5,$B$20:$F$20)*INDEX($E$24:$J$33,MATCH(N$3,$D$24:$D$33,0),MATCH($A$20,$E$23:$J$23,0)))/250,0) -> 0.032 | O5: =IFERROR((SUMIF($B$9:$F$9,$M5,$B$10:$F$10)*INDEX($E$24:$J$33,MATCH(O$3,$D$24:$D$33,0),MATCH($A$10,$E$23:$J$23,0))+SUMIF($B$11:$F$11,$M5,$B$12:$F$12)*INDEX($E$24:$J$33,MATCH(O$3,$D$24:$D$33,0),MATCH($A$12,$E$23:$J$23,0))+SUMIF($B$13:$F$13,$M5,$B$14:$F$14)*INDEX($E$24:$J$33,MATCH(O$3,$D$24:$D$33,0),MATCH($A$14,$E$23:$J$23,0))+SUMIF($B$15:$F$15,$M5,$B$16:$F$16)*INDEX($E$24:$J$33,MATCH(O$3,$D$24:$D$33,0),MATCH($A$16,$E$23:$J$23,0))+SUMIF($B$17:$F$17,$M5,$B$18:$F$18)*INDEX($E$24:$J$33,MATCH(O$3,$D$24:$D$33,0),MATCH($A$18,$E$23:$J$23,0))+SUMIF($B$19:$F$19,$M5,$B$20:$F$20)*INDEX($E$24:$J$33,MATCH(O$3,$D$24:$D$33,0),MATCH($A$20,$E$23:$J$23,0)))/250,0) -> 0.024 | P5: =IFERROR((SUMIF($B$9:$F$9,$M5,$B$10:$F$10)*INDEX($E$24:$J$33,MATCH(P$3,$D$24:$D$33,0),MATCH($A$10,$E$23:$J$23,0))+SUMIF($B$11:$F$11,$M5,$B$12:$F$12)*INDEX($E$24:$J$33,MATCH(P$3,$D$24:$D$33,0),MATCH($A$12,$E$23:$J$23,0))+SUMIF($B$13:$F$13,$M5,$B$14:$F$14)*INDEX($E$24:$J$33,MATCH(P$3,$D$24:$D$33,0),MATCH($A$14,$E$23:$J$23,0))+SUMIF($B$15:$F$15,$M5,$B$16:$F$16)*INDEX($E$24:$J$33,MATCH(P$3,$D$24:$D$33,0),MATCH($A$16,$E$23:$J$23,0))+SUMIF($B$17:$F$17,$M5,$B$18:$F$18)*INDEX($E$24:$J$33,MATCH(P$3,$D$24:$D$33,0),MATCH($A$18,$E$23:$J$23,0))+SUMIF($B$19:$F$19,$M5,$B$20:$F$20)*INDEX($E$24:$J$33,MATCH(P$3,$D$24:$D$33,0),MATCH($A$20,$E$23:$J$23,0)))/250,0) -> 0.024 | Q5: =IFERROR((SUMIF($B$9:$F$9,$M5,$B$10:$F$10)*INDEX($E$24:$J$33,MATCH(Q$3,$D$24:$D$33,0),MATCH($A$10,$E$23:$J$23,0))+SUMIF($B$11:$F$11,$M5,$B$12:$F$12)*INDEX($E$24:$J$33,MATCH(Q$3,$D$24:$D$33,0),MATCH($A$12,$E$23:$J$23,0))+SUMIF($B$13:$F$13,$M5,$B$14:$F$14)*INDEX($E$24:$J$33,MATCH(Q$3,$D$24:$D$33,0),MATCH($A$14,$E$23:$J$23,0))+SUMIF($B$15:$F$15,$M5,$B$16:$F$16)*INDEX($E$24:$J$33,MATCH(Q$3,$D$24:$D$33,0),MATCH($A$16,$E$23:$J$23,0))+SUMIF($B$17:$F$17,$M5,$B$18:$F$18)*INDEX($E$24:$J$33,MATCH(Q$3,$D$24:$D$33,0),MATCH($A$18,$E$23:$J$23,0))+SUMIF($B$19:$F$19,$M5,$B$20:$F$20)*INDEX($E$24:$J$33,MATCH(Q$3,$D$24:$D$33,0),MATCH($A$20,$E$23:$J$23,0)))/250,0) -> 0.016 | R5: =IFERROR((SUMIF($B$9:$F$9,$M5,$B$10:$F$10)*INDEX($E$24:$J$33,MATCH(R$3,$D$24:$D$33,0),MATCH($A$10,$E$23:$J$23,0))+SUMIF($B$11:$F$11,$M5,$B$12:$F$12)*INDEX($E$24:$J$33,MATCH(R$3,$D$24:$D$33,0),MATCH($A$12,$E$23:$J$23,0))+SUMIF($B$13:$F$13,$M5,$B$14:$F$14)*INDEX($E$24:$J$33,MATCH(R$3,$D$24:$D$33,0),MATCH($A$14,$E$23:$J$23,0))+SUMIF($B$15:$F$15,$M5,$B$16:$F$16)*INDEX($E$24:$J$33,MATCH(R$3,$D$24:$D$33,0),MATCH($A$16,$E$23:$J$23,0))+SUMIF($B$17:$F$17,$M5,$B$18:$F$18)*INDEX($E$24:$J$33,MATCH(R$3,$D$24:$D$33,0),MATCH($A$18,$E$23:$J$23,0))+SUMIF($B$19:$F$19,$M5,$B$20:$F$20)*INDEX($E$24:$J$33,MATCH(R$3,$D$24:$D$33,0),MATCH($A$20,$E$23:$J$23,0)))/250,0) -> 0.012 | S5: =IFERROR((SUMIF($B$9:$F$9,$M5,$B$10:$F$10)*INDEX($E$24:$J$33,MATCH(S$3,$D$24:$D$33,0),MATCH($A$10,$E$23:$J$23,0))+SUMIF($B$11:$F$11,$M5,$B$12:$F$12)*INDEX($E$24:$J$33,MATCH(S$3,$D$24:$D$33,0),MATCH($A$12,$E$23:$J$23,0))+SUMIF($B$13:$F$13,$M5,$B$14:$F$14)*INDEX($E$24:$J$33,MATCH(S$3,$D$24:$D$33,0),MATCH($A$14,$E$23:$J$23,0))+SUMIF($B$15:$F$15,$M5,$B$16:$F$16)*INDEX($E$24:$J$33,MATCH(S$3,$D$24:$D$33,0),MATCH($A$16,$E$23:$J$23,0))+SUMIF($B$17:$F$17,$M5,$B$18:$F$18)*INDEX($E$24:$J$33,MATCH(S$3,$D$24:$D$33,0),MATCH($A$18,$E$23:$J$23,0))+SUMIF($B$19:$F$19,$M5,$B$20:$F$20)*INDEX($E$24:$J$33,MATCH(S$3,$D$24:$D$33,0),MATCH($A$20,$E$23:$J$23,0)))/250,0) -> 0.008 | T5: =IFERROR((SUMIF($B$9:$F$9,$M5,$B$10:$F$10)*INDEX($E$24:$J$33,MATCH(T$3,$D$24:$D$33,0),MATCH($A$10,$E$23:$J$23,0))+SUMIF($B$11:$F$11,$M5,$B$12:$F$12)*INDEX($E$24:$J$33,MATCH(T$3,$D$24:$D$33,0),MATCH($A$12,$E$23:$J$23,0))+SUMIF($B$13:$F$13,$M5,$B$14:$F$14)*INDEX($E$24:$J$33,MATCH(T$3,$D$24:$D$33,0),MATCH($A$14,$E$23:$J$23,0))+SUMIF($B$15:$F$15,$M5,$B$16:$F$16)*INDEX($E$24:$J$33,MATCH(T$3,$D$24:$D$33,0),MATCH($A$16,$E$23:$J$23,0))+SUMIF($B$17:$F$17,$M5,$B$18:$F$18)*INDEX($E$24:$J$33,MATCH(T$3,$D$24:$D$33,0),MATCH($A$18,$E$23:$J$23,0))+SUMIF($B$19:$F$19,$M5,$B$20:$F$20)*INDEX($E$24:$J$33,MATCH(T$3,$D$24:$D$33,0),MATCH($A$20,$E$23:$J$23,0)))/250,0) -> 0.004 | U5: =IFERROR((SUMIF($B$9:$F$9,$M5,$B$10:$F$10)*INDEX($E$24:$J$33,MATCH(U$3,$D$24:$D$33,0),MATCH($A$10,$E$23:$J$23,0))+SUMIF($B$11:$F$11,$M5,$B$12:$F$12)*INDEX($E$24:$J$33,MATCH(U$3,$D$24:$D$33,0),MATCH($A$12,$E$23:$J$23,0))+SUMIF($B$13:$F$13,$M5,$B$14:$F$14)*INDEX($E$24:$J$33,MATCH(U$3,$D$24:$D$33,0),MATCH($A$14,$E$23:$J$23,0))+SUMIF($B$15:$F$15,$M5,$B$16:$F$16)*INDEX($E$24:$J$33,MATCH(U$3,$D$24:$D$33,0),MATCH($A$16,$E$23:$J$23,0))+SUMIF($B$17:$F$17,$M5,$B$18:$F$18)*INDEX($E$24:$J$33,MATCH(U$3,$D$24:$D$33,0),MATCH($A$18,$E$23:$J$23,0))+SUMIF($B$19:$F$19,$M5,$B$20:$F$20)*INDEX($E$24:$J$33,MATCH(U$3,$D$24:$D$33,0),MATCH($A$20,$E$23:$J$23,0)))/250,0) -> 0.008 | ... W5: =IFERROR((SUMIF($B$9:$F$9,$M5,$B$10:$F$10)*INDEX($E$24:$J$33,MATCH(W$3,$D$24:$D$33,0),MATCH($A$10,$E$23:$J$23,0))+SUMIF($B$11:$F$11,$M5,$B$12:$F$12)*INDEX($E$24:$J$33,MATCH(W$3,$D$24:$D$33,0),MATCH($A$12,$E$23:$J$23,0))+SUMIF($B$13:$F$13,$M5,$B$14:$F$14)*INDEX($E$24:$J$33,MATCH(W$3,$D$24:$D$33,0),MATCH($A$14,$E$23:$J$23,0))+SUMIF($B$15:$F$15,$M5,$B$16:$F$16)*INDEX($E$24:$J$33,MATCH(W$3,$D$24:$D$33,0),MATCH($A$16,$E$23:$J$23,0))+SUMIF($B$17:$F$17,$M5,$B$18:$F$18)*INDEX($E$24:$J$33,MATCH(W$3,$D$24:$D$33,0),MATCH($A$18,$E$23:$J$23,0))+SUMIF($B$19:$F$19,$M5,$B$20:$F$20)*INDEX($E$24:$J$33,MATCH(W$3,$D$24:$D$33,0),MATCH($A$20,$E$23:$J$23,0)))/250,0) -> 0.004 | Y5: Bale Icon | Z5: GARETH BALE | AA5: 186 | AB5: 87 | AC5: =ROUND((AB5+AA5-100)/2,0) -> 87 | AD5: =AC5-AB5 -> 0 | AE5: Wikidata P2048 và hồ sơ CLB/giải đấu; có thể hiệu chỉnh
A6: Phòng thủ (DEF) | B6: Đánh chặn, Tắc bóng, Xoạc bóng, Lấy bóng, Đánh đầu | F6: Shield | M6: =$A26 -> POS | N6: =IFERROR((SUMIF($B$9:$F$9,$M6,$B$10:$F$10)*INDEX($E$24:$J$33,MATCH(N$3,$D$24:$D$33,0),MATCH($A$10,$E$23:$J$23,0))+SUMIF($B$11:$F$11,$M6,$B$12:$F$12)*INDEX($E$24:$J$33,MATCH(N$3,$D$24:$D$33,0),MATCH($A$12,$E$23:$J$23,0))+SUMIF($B$13:$F$13,$M6,$B$14:$F$14)*INDEX($E$24:$J$33,MATCH(N$3,$D$24:$D$33,0),MATCH($A$14,$E$23:$J$23,0))+SUMIF($B$15:$F$15,$M6,$B$16:$F$16)*INDEX($E$24:$J$33,MATCH(N$3,$D$24:$D$33,0),MATCH($A$16,$E$23:$J$23,0))+SUMIF($B$17:$F$17,$M6,$B$18:$F$18)*INDEX($E$24:$J$33,MATCH(N$3,$D$24:$D$33,0),MATCH($A$18,$E$23:$J$23,0))+SUMIF($B$19:$F$19,$M6,$B$20:$F$20)*INDEX($E$24:$J$33,MATCH(N$3,$D$24:$D$33,0),MATCH($A$20,$E$23:$J$23,0)))/250,0) -> 0.088 | O6: =IFERROR((SUMIF($B$9:$F$9,$M6,$B$10:$F$10)*INDEX($E$24:$J$33,MATCH(O$3,$D$24:$D$33,0),MATCH($A$10,$E$23:$J$23,0))+SUMIF($B$11:$F$11,$M6,$B$12:$F$12)*INDEX($E$24:$J$33,MATCH(O$3,$D$24:$D$33,0),MATCH($A$12,$E$23:$J$23,0))+SUMIF($B$13:$F$13,$M6,$B$14:$F$14)*INDEX($E$24:$J$33,MATCH(O$3,$D$24:$D$33,0),MATCH($A$14,$E$23:$J$23,0))+SUMIF($B$15:$F$15,$M6,$B$16:$F$16)*INDEX($E$24:$J$33,MATCH(O$3,$D$24:$D$33,0),MATCH($A$16,$E$23:$J$23,0))+SUMIF($B$17:$F$17,$M6,$B$18:$F$18)*INDEX($E$24:$J$33,MATCH(O$3,$D$24:$D$33,0),MATCH($A$18,$E$23:$J$23,0))+SUMIF($B$19:$F$19,$M6,$B$20:$F$20)*INDEX($E$24:$J$33,MATCH(O$3,$D$24:$D$33,0),MATCH($A$20,$E$23:$J$23,0)))/250,0) -> 0.072 | P6: =IFERROR((SUMIF($B$9:$F$9,$M6,$B$10:$F$10)*INDEX($E$24:$J$33,MATCH(P$3,$D$24:$D$33,0),MATCH($A$10,$E$23:$J$23,0))+SUMIF($B$11:$F$11,$M6,$B$12:$F$12)*INDEX($E$24:$J$33,MATCH(P$3,$D$24:$D$33,0),MATCH($A$12,$E$23:$J$23,0))+SUMIF($B$13:$F$13,$M6,$B$14:$F$14)*INDEX($E$24:$J$33,MATCH(P$3,$D$24:$D$33,0),MATCH($A$14,$E$23:$J$23,0))+SUMIF($B$15:$F$15,$M6,$B$16:$F$16)*INDEX($E$24:$J$33,MATCH(P$3,$D$24:$D$33,0),MATCH($A$16,$E$23:$J$23,0))+SUMIF($B$17:$F$17,$M6,$B$18:$F$18)*INDEX($E$24:$J$33,MATCH(P$3,$D$24:$D$33,0),MATCH($A$18,$E$23:$J$23,0))+SUMIF($B$19:$F$19,$M6,$B$20:$F$20)*INDEX($E$24:$J$33,MATCH(P$3,$D$24:$D$33,0),MATCH($A$20,$E$23:$J$23,0)))/250,0) -> 0.072 | Q6: =IFERROR((SUMIF($B$9:$F$9,$M6,$B$10:$F$10)*INDEX($E$24:$J$33,MATCH(Q$3,$D$24:$D$33,0),MATCH($A$10,$E$23:$J$23,0))+SUMIF($B$11:$F$11,$M6,$B$12:$F$12)*INDEX($E$24:$J$33,MATCH(Q$3,$D$24:$D$33,0),MATCH($A$12,$E$23:$J$23,0))+SUMIF($B$13:$F$13,$M6,$B$14:$F$14)*INDEX($E$24:$J$33,MATCH(Q$3,$D$24:$D$33,0),MATCH($A$14,$E$23:$J$23,0))+SUMIF($B$15:$F$15,$M6,$B$16:$F$16)*INDEX($E$24:$J$33,MATCH(Q$3,$D$24:$D$33,0),MATCH($A$16,$E$23:$J$23,0))+SUMIF($B$17:$F$17,$M6,$B$18:$F$18)*INDEX($E$24:$J$33,MATCH(Q$3,$D$24:$D$33,0),MATCH($A$18,$E$23:$J$23,0))+SUMIF($B$19:$F$19,$M6,$B$20:$F$20)*INDEX($E$24:$J$33,MATCH(Q$3,$D$24:$D$33,0),MATCH($A$20,$E$23:$J$23,0)))/250,0) -> 0.056 | R6: =IFERROR((SUMIF($B$9:$F$9,$M6,$B$10:$F$10)*INDEX($E$24:$J$33,MATCH(R$3,$D$24:$D$33,0),MATCH($A$10,$E$23:$J$23,0))+SUMIF($B$11:$F$11,$M6,$B$12:$F$12)*INDEX($E$24:$J$33,MATCH(R$3,$D$24:$D$33,0),MATCH($A$12,$E$23:$J$23,0))+SUMIF($B$13:$F$13,$M6,$B$14:$F$14)*INDEX($E$24:$J$33,MATCH(R$3,$D$24:$D$33,0),MATCH($A$14,$E$23:$J$23,0))+SUMIF($B$15:$F$15,$M6,$B$16:$F$16)*INDEX($E$24:$J$33,MATCH(R$3,$D$24:$D$33,0),MATCH($A$16,$E$23:$J$23,0))+SUMIF($B$17:$F$17,$M6,$B$18:$F$18)*INDEX($E$24:$J$33,MATCH(R$3,$D$24:$D$33,0),MATCH($A$18,$E$23:$J$23,0))+SUMIF($B$19:$F$19,$M6,$B$20:$F$20)*INDEX($E$24:$J$33,MATCH(R$3,$D$24:$D$33,0),MATCH($A$20,$E$23:$J$23,0)))/250,0) -> 0.048 | S6: =IFERROR((SUMIF($B$9:$F$9,$M6,$B$10:$F$10)*INDEX($E$24:$J$33,MATCH(S$3,$D$24:$D$33,0),MATCH($A$10,$E$23:$J$23,0))+SUMIF($B$11:$F$11,$M6,$B$12:$F$12)*INDEX($E$24:$J$33,MATCH(S$3,$D$24:$D$33,0),MATCH($A$12,$E$23:$J$23,0))+SUMIF($B$13:$F$13,$M6,$B$14:$F$14)*INDEX($E$24:$J$33,MATCH(S$3,$D$24:$D$33,0),MATCH($A$14,$E$23:$J$23,0))+SUMIF($B$15:$F$15,$M6,$B$16:$F$16)*INDEX($E$24:$J$33,MATCH(S$3,$D$24:$D$33,0),MATCH($A$16,$E$23:$J$23,0))+SUMIF($B$17:$F$17,$M6,$B$18:$F$18)*INDEX($E$24:$J$33,MATCH(S$3,$D$24:$D$33,0),MATCH($A$18,$E$23:$J$23,0))+SUMIF($B$19:$F$19,$M6,$B$20:$F$20)*INDEX($E$24:$J$33,MATCH(S$3,$D$24:$D$33,0),MATCH($A$20,$E$23:$J$23,0)))/250,0) -> 0.04 | T6: =IFERROR((SUMIF($B$9:$F$9,$M6,$B$10:$F$10)*INDEX($E$24:$J$33,MATCH(T$3,$D$24:$D$33,0),MATCH($A$10,$E$23:$J$23,0))+SUMIF($B$11:$F$11,$M6,$B$12:$F$12)*INDEX($E$24:$J$33,MATCH(T$3,$D$24:$D$33,0),MATCH($A$12,$E$23:$J$23,0))+SUMIF($B$13:$F$13,$M6,$B$14:$F$14)*INDEX($E$24:$J$33,MATCH(T$3,$D$24:$D$33,0),MATCH($A$14,$E$23:$J$23,0))+SUMIF($B$15:$F$15,$M6,$B$16:$F$16)*INDEX($E$24:$J$33,MATCH(T$3,$D$24:$D$33,0),MATCH($A$16,$E$23:$J$23,0))+SUMIF($B$17:$F$17,$M6,$B$18:$F$18)*INDEX($E$24:$J$33,MATCH(T$3,$D$24:$D$33,0),MATCH($A$18,$E$23:$J$23,0))+SUMIF($B$19:$F$19,$M6,$B$20:$F$20)*INDEX($E$24:$J$33,MATCH(T$3,$D$24:$D$33,0),MATCH($A$20,$E$23:$J$23,0)))/250,0) -> 0.032 | U6: =IFERROR((SUMIF($B$9:$F$9,$M6,$B$10:$F$10)*INDEX($E$24:$J$33,MATCH(U$3,$D$24:$D$33,0),MATCH($A$10,$E$23:$J$23,0))+SUMIF($B$11:$F$11,$M6,$B$12:$F$12)*INDEX($E$24:$J$33,MATCH(U$3,$D$24:$D$33,0),MATCH($A$12,$E$23:$J$23,0))+SUMIF($B$13:$F$13,$M6,$B$14:$F$14)*INDEX($E$24:$J$33,MATCH(U$3,$D$24:$D$33,0),MATCH($A$14,$E$23:$J$23,0))+SUMIF($B$15:$F$15,$M6,$B$16:$F$16)*INDEX($E$24:$J$33,MATCH(U$3,$D$24:$D$33,0),MATCH($A$16,$E$23:$J$23,0))+SUMIF($B$17:$F$17,$M6,$B$18:$F$18)*INDEX($E$24:$J$33,MATCH(U$3,$D$24:$D$33,0),MATCH($A$18,$E$23:$J$23,0))+SUMIF($B$19:$F$19,$M6,$B$20:$F$20)*INDEX($E$24:$J$33,MATCH(U$3,$D$24:$D$33,0),MATCH($A$20,$E$23:$J$23,0)))/250,0) -> 0.04 | ... W6: =IFERROR((SUMIF($B$9:$F$9,$M6,$B$10:$F$10)*INDEX($E$24:$J$33,MATCH(W$3,$D$24:$D$33,0),MATCH($A$10,$E$23:$J$23,0))+SUMIF($B$11:$F$11,$M6,$B$12:$F$12)*INDEX($E$24:$J$33,MATCH(W$3,$D$24:$D$33,0),MATCH($A$12,$E$23:$J$23,0))+SUMIF($B$13:$F$13,$M6,$B$14:$F$14)*INDEX($E$24:$J$33,MATCH(W$3,$D$24:$D$33,0),MATCH($A$14,$E$23:$J$23,0))+SUMIF($B$15:$F$15,$M6,$B$16:$F$16)*INDEX($E$24:$J$33,MATCH(W$3,$D$24:$D$33,0),MATCH($A$16,$E$23:$J$23,0))+SUMIF($B$17:$F$17,$M6,$B$18:$F$18)*INDEX($E$24:$J$33,MATCH(W$3,$D$24:$D$33,0),MATCH($A$18,$E$23:$J$23,0))+SUMIF($B$19:$F$19,$M6,$B$20:$F$20)*INDEX($E$24:$J$33,MATCH(W$3,$D$24:$D$33,0),MATCH($A$20,$E$23:$J$23,0)))/250,0) -> 0.032 | Y6: CR7 Icon | Z6: CRISTIANO RONALDO | AA6: 187 | AB6: 94 | AC6: =ROUND((AB6+AA6-100)/2,0) -> 91 | AD6: =AC6-AB6 -> -3 | AE6: Wikidata P2048 và hồ sơ CLB/giải đấu; có thể hiệu chỉnh
M7: =$A27 -> HEA | N7: =IFERROR((SUMIF($B$9:$F$9,$M7,$B$10:$F$10)*INDEX($E$24:$J$33,MATCH(N$3,$D$24:$D$33,0),MATCH($A$10,$E$23:$J$23,0))+SUMIF($B$11:$F$11,$M7,$B$12:$F$12)*INDEX($E$24:$J$33,MATCH(N$3,$D$24:$D$33,0),MATCH($A$12,$E$23:$J$23,0))+SUMIF($B$13:$F$13,$M7,$B$14:$F$14)*INDEX($E$24:$J$33,MATCH(N$3,$D$24:$D$33,0),MATCH($A$14,$E$23:$J$23,0))+SUMIF($B$15:$F$15,$M7,$B$16:$F$16)*INDEX($E$24:$J$33,MATCH(N$3,$D$24:$D$33,0),MATCH($A$16,$E$23:$J$23,0))+SUMIF($B$17:$F$17,$M7,$B$18:$F$18)*INDEX($E$24:$J$33,MATCH(N$3,$D$24:$D$33,0),MATCH($A$18,$E$23:$J$23,0))+SUMIF($B$19:$F$19,$M7,$B$20:$F$20)*INDEX($E$24:$J$33,MATCH(N$3,$D$24:$D$33,0),MATCH($A$20,$E$23:$J$23,0)))/250,0) -> 0.054 | O7: =IFERROR((SUMIF($B$9:$F$9,$M7,$B$10:$F$10)*INDEX($E$24:$J$33,MATCH(O$3,$D$24:$D$33,0),MATCH($A$10,$E$23:$J$23,0))+SUMIF($B$11:$F$11,$M7,$B$12:$F$12)*INDEX($E$24:$J$33,MATCH(O$3,$D$24:$D$33,0),MATCH($A$12,$E$23:$J$23,0))+SUMIF($B$13:$F$13,$M7,$B$14:$F$14)*INDEX($E$24:$J$33,MATCH(O$3,$D$24:$D$33,0),MATCH($A$14,$E$23:$J$23,0))+SUMIF($B$15:$F$15,$M7,$B$16:$F$16)*INDEX($E$24:$J$33,MATCH(O$3,$D$24:$D$33,0),MATCH($A$16,$E$23:$J$23,0))+SUMIF($B$17:$F$17,$M7,$B$18:$F$18)*INDEX($E$24:$J$33,MATCH(O$3,$D$24:$D$33,0),MATCH($A$18,$E$23:$J$23,0))+SUMIF($B$19:$F$19,$M7,$B$20:$F$20)*INDEX($E$24:$J$33,MATCH(O$3,$D$24:$D$33,0),MATCH($A$20,$E$23:$J$23,0)))/250,0) -> 0.042 | P7: =IFERROR((SUMIF($B$9:$F$9,$M7,$B$10:$F$10)*INDEX($E$24:$J$33,MATCH(P$3,$D$24:$D$33,0),MATCH($A$10,$E$23:$J$23,0))+SUMIF($B$11:$F$11,$M7,$B$12:$F$12)*INDEX($E$24:$J$33,MATCH(P$3,$D$24:$D$33,0),MATCH($A$12,$E$23:$J$23,0))+SUMIF($B$13:$F$13,$M7,$B$14:$F$14)*INDEX($E$24:$J$33,MATCH(P$3,$D$24:$D$33,0),MATCH($A$14,$E$23:$J$23,0))+SUMIF($B$15:$F$15,$M7,$B$16:$F$16)*INDEX($E$24:$J$33,MATCH(P$3,$D$24:$D$33,0),MATCH($A$16,$E$23:$J$23,0))+SUMIF($B$17:$F$17,$M7,$B$18:$F$18)*INDEX($E$24:$J$33,MATCH(P$3,$D$24:$D$33,0),MATCH($A$18,$E$23:$J$23,0))+SUMIF($B$19:$F$19,$M7,$B$20:$F$20)*INDEX($E$24:$J$33,MATCH(P$3,$D$24:$D$33,0),MATCH($A$20,$E$23:$J$23,0)))/250,0) -> 0.042 | Q7: =IFERROR((SUMIF($B$9:$F$9,$M7,$B$10:$F$10)*INDEX($E$24:$J$33,MATCH(Q$3,$D$24:$D$33,0),MATCH($A$10,$E$23:$J$23,0))+SUMIF($B$11:$F$11,$M7,$B$12:$F$12)*INDEX($E$24:$J$33,MATCH(Q$3,$D$24:$D$33,0),MATCH($A$12,$E$23:$J$23,0))+SUMIF($B$13:$F$13,$M7,$B$14:$F$14)*INDEX($E$24:$J$33,MATCH(Q$3,$D$24:$D$33,0),MATCH($A$14,$E$23:$J$23,0))+SUMIF($B$15:$F$15,$M7,$B$16:$F$16)*INDEX($E$24:$J$33,MATCH(Q$3,$D$24:$D$33,0),MATCH($A$16,$E$23:$J$23,0))+SUMIF($B$17:$F$17,$M7,$B$18:$F$18)*INDEX($E$24:$J$33,MATCH(Q$3,$D$24:$D$33,0),MATCH($A$18,$E$23:$J$23,0))+SUMIF($B$19:$F$19,$M7,$B$20:$F$20)*INDEX($E$24:$J$33,MATCH(Q$3,$D$24:$D$33,0),MATCH($A$20,$E$23:$J$23,0)))/250,0) -> 0.03 | R7: =IFERROR((SUMIF($B$9:$F$9,$M7,$B$10:$F$10)*INDEX($E$24:$J$33,MATCH(R$3,$D$24:$D$33,0),MATCH($A$10,$E$23:$J$23,0))+SUMIF($B$11:$F$11,$M7,$B$12:$F$12)*INDEX($E$24:$J$33,MATCH(R$3,$D$24:$D$33,0),MATCH($A$12,$E$23:$J$23,0))+SUMIF($B$13:$F$13,$M7,$B$14:$F$14)*INDEX($E$24:$J$33,MATCH(R$3,$D$24:$D$33,0),MATCH($A$14,$E$23:$J$23,0))+SUMIF($B$15:$F$15,$M7,$B$16:$F$16)*INDEX($E$24:$J$33,MATCH(R$3,$D$24:$D$33,0),MATCH($A$16,$E$23:$J$23,0))+SUMIF($B$17:$F$17,$M7,$B$18:$F$18)*INDEX($E$24:$J$33,MATCH(R$3,$D$24:$D$33,0),MATCH($A$18,$E$23:$J$23,0))+SUMIF($B$19:$F$19,$M7,$B$20:$F$20)*INDEX($E$24:$J$33,MATCH(R$3,$D$24:$D$33,0),MATCH($A$20,$E$23:$J$23,0)))/250,0) -> 0.036 | S7: =IFERROR((SUMIF($B$9:$F$9,$M7,$B$10:$F$10)*INDEX($E$24:$J$33,MATCH(S$3,$D$24:$D$33,0),MATCH($A$10,$E$23:$J$23,0))+SUMIF($B$11:$F$11,$M7,$B$12:$F$12)*INDEX($E$24:$J$33,MATCH(S$3,$D$24:$D$33,0),MATCH($A$12,$E$23:$J$23,0))+SUMIF($B$13:$F$13,$M7,$B$14:$F$14)*INDEX($E$24:$J$33,MATCH(S$3,$D$24:$D$33,0),MATCH($A$14,$E$23:$J$23,0))+SUMIF($B$15:$F$15,$M7,$B$16:$F$16)*INDEX($E$24:$J$33,MATCH(S$3,$D$24:$D$33,0),MATCH($A$16,$E$23:$J$23,0))+SUMIF($B$17:$F$17,$M7,$B$18:$F$18)*INDEX($E$24:$J$33,MATCH(S$3,$D$24:$D$33,0),MATCH($A$18,$E$23:$J$23,0))+SUMIF($B$19:$F$19,$M7,$B$20:$F$20)*INDEX($E$24:$J$33,MATCH(S$3,$D$24:$D$33,0),MATCH($A$20,$E$23:$J$23,0)))/250,0) -> 0.036 | T7: =IFERROR((SUMIF($B$9:$F$9,$M7,$B$10:$F$10)*INDEX($E$24:$J$33,MATCH(T$3,$D$24:$D$33,0),MATCH($A$10,$E$23:$J$23,0))+SUMIF($B$11:$F$11,$M7,$B$12:$F$12)*INDEX($E$24:$J$33,MATCH(T$3,$D$24:$D$33,0),MATCH($A$12,$E$23:$J$23,0))+SUMIF($B$13:$F$13,$M7,$B$14:$F$14)*INDEX($E$24:$J$33,MATCH(T$3,$D$24:$D$33,0),MATCH($A$14,$E$23:$J$23,0))+SUMIF($B$15:$F$15,$M7,$B$16:$F$16)*INDEX($E$24:$J$33,MATCH(T$3,$D$24:$D$33,0),MATCH($A$16,$E$23:$J$23,0))+SUMIF($B$17:$F$17,$M7,$B$18:$F$18)*INDEX($E$24:$J$33,MATCH(T$3,$D$24:$D$33,0),MATCH($A$18,$E$23:$J$23,0))+SUMIF($B$19:$F$19,$M7,$B$20:$F$20)*INDEX($E$24:$J$33,MATCH(T$3,$D$24:$D$33,0),MATCH($A$20,$E$23:$J$23,0)))/250,0) -> 0.042 | U7: =IFERROR((SUMIF($B$9:$F$9,$M7,$B$10:$F$10)*INDEX($E$24:$J$33,MATCH(U$3,$D$24:$D$33,0),MATCH($A$10,$E$23:$J$23,0))+SUMIF($B$11:$F$11,$M7,$B$12:$F$12)*INDEX($E$24:$J$33,MATCH(U$3,$D$24:$D$33,0),MATCH($A$12,$E$23:$J$23,0))+SUMIF($B$13:$F$13,$M7,$B$14:$F$14)*INDEX($E$24:$J$33,MATCH(U$3,$D$24:$D$33,0),MATCH($A$14,$E$23:$J$23,0))+SUMIF($B$15:$F$15,$M7,$B$16:$F$16)*INDEX($E$24:$J$33,MATCH(U$3,$D$24:$D$33,0),MATCH($A$16,$E$23:$J$23,0))+SUMIF($B$17:$F$17,$M7,$B$18:$F$18)*INDEX($E$24:$J$33,MATCH(U$3,$D$24:$D$33,0),MATCH($A$18,$E$23:$J$23,0))+SUMIF($B$19:$F$19,$M7,$B$20:$F$20)*INDEX($E$24:$J$33,MATCH(U$3,$D$24:$D$33,0),MATCH($A$20,$E$23:$J$23,0)))/250,0) -> 0.036 | ... W7: =IFERROR((SUMIF($B$9:$F$9,$M7,$B$10:$F$10)*INDEX($E$24:$J$33,MATCH(W$3,$D$24:$D$33,0),MATCH($A$10,$E$23:$J$23,0))+SUMIF($B$11:$F$11,$M7,$B$12:$F$12)*INDEX($E$24:$J$33,MATCH(W$3,$D$24:$D$33,0),MATCH($A$12,$E$23:$J$23,0))+SUMIF($B$13:$F$13,$M7,$B$14:$F$14)*INDEX($E$24:$J$33,MATCH(W$3,$D$24:$D$33,0),MATCH($A$14,$E$23:$J$23,0))+SUMIF($B$15:$F$15,$M7,$B$16:$F$16)*INDEX($E$24:$J$33,MATCH(W$3,$D$24:$D$33,0),MATCH($A$16,$E$23:$J$23,0))+SUMIF($B$17:$F$17,$M7,$B$18:$F$18)*INDEX($E$24:$J$33,MATCH(W$3,$D$24:$D$33,0),MATCH($A$18,$E$23:$J$23,0))+SUMIF($B$19:$F$19,$M7,$B$20:$F$20)*INDEX($E$24:$J$33,MATCH(W$3,$D$24:$D$33,0),MATCH($A$20,$E$23:$J$23,0)))/250,0) -> 0.06 | Y7: Neymar Icon | Z7: NEYMAR JR | AA7: 175 | AB7: 71 | AC7: =ROUND((AB7+AA7-100)/2,0) -> 73 | AD7: =AC7-AB7 -> 2 | AE7: Wikidata P2048 và hồ sơ CLB/giải đấu; có thể hiệu chỉnh
M8: =$A28 -> CRO | N8: =IFERROR((SUMIF($B$9:$F$9,$M8,$B$10:$F$10)*INDEX($E$24:$J$33,MATCH(N$3,$D$24:$D$33,0),MATCH($A$10,$E$23:$J$23,0))+SUMIF($B$11:$F$11,$M8,$B$12:$F$12)*INDEX($E$24:$J$33,MATCH(N$3,$D$24:$D$33,0),MATCH($A$12,$E$23:$J$23,0))+SUMIF($B$13:$F$13,$M8,$B$14:$F$14)*INDEX($E$24:$J$33,MATCH(N$3,$D$24:$D$33,0),MATCH($A$14,$E$23:$J$23,0))+SUMIF($B$15:$F$15,$M8,$B$16:$F$16)*INDEX($E$24:$J$33,MATCH(N$3,$D$24:$D$33,0),MATCH($A$16,$E$23:$J$23,0))+SUMIF($B$17:$F$17,$M8,$B$18:$F$18)*INDEX($E$24:$J$33,MATCH(N$3,$D$24:$D$33,0),MATCH($A$18,$E$23:$J$23,0))+SUMIF($B$19:$F$19,$M8,$B$20:$F$20)*INDEX($E$24:$J$33,MATCH(N$3,$D$24:$D$33,0),MATCH($A$20,$E$23:$J$23,0)))/250,0) -> 0.048 | O8: =IFERROR((SUMIF($B$9:$F$9,$M8,$B$10:$F$10)*INDEX($E$24:$J$33,MATCH(O$3,$D$24:$D$33,0),MATCH($A$10,$E$23:$J$23,0))+SUMIF($B$11:$F$11,$M8,$B$12:$F$12)*INDEX($E$24:$J$33,MATCH(O$3,$D$24:$D$33,0),MATCH($A$12,$E$23:$J$23,0))+SUMIF($B$13:$F$13,$M8,$B$14:$F$14)*INDEX($E$24:$J$33,MATCH(O$3,$D$24:$D$33,0),MATCH($A$14,$E$23:$J$23,0))+SUMIF($B$15:$F$15,$M8,$B$16:$F$16)*INDEX($E$24:$J$33,MATCH(O$3,$D$24:$D$33,0),MATCH($A$16,$E$23:$J$23,0))+SUMIF($B$17:$F$17,$M8,$B$18:$F$18)*INDEX($E$24:$J$33,MATCH(O$3,$D$24:$D$33,0),MATCH($A$18,$E$23:$J$23,0))+SUMIF($B$19:$F$19,$M8,$B$20:$F$20)*INDEX($E$24:$J$33,MATCH(O$3,$D$24:$D$33,0),MATCH($A$20,$E$23:$J$23,0)))/250,0) -> 0.036 | P8: =IFERROR((SUMIF($B$9:$F$9,$M8,$B$10:$F$10)*INDEX($E$24:$J$33,MATCH(P$3,$D$24:$D$33,0),MATCH($A$10,$E$23:$J$23,0))+SUMIF($B$11:$F$11,$M8,$B$12:$F$12)*INDEX($E$24:$J$33,MATCH(P$3,$D$24:$D$33,0),MATCH($A$12,$E$23:$J$23,0))+SUMIF($B$13:$F$13,$M8,$B$14:$F$14)*INDEX($E$24:$J$33,MATCH(P$3,$D$24:$D$33,0),MATCH($A$14,$E$23:$J$23,0))+SUMIF($B$15:$F$15,$M8,$B$16:$F$16)*INDEX($E$24:$J$33,MATCH(P$3,$D$24:$D$33,0),MATCH($A$16,$E$23:$J$23,0))+SUMIF($B$17:$F$17,$M8,$B$18:$F$18)*INDEX($E$24:$J$33,MATCH(P$3,$D$24:$D$33,0),MATCH($A$18,$E$23:$J$23,0))+SUMIF($B$19:$F$19,$M8,$B$20:$F$20)*INDEX($E$24:$J$33,MATCH(P$3,$D$24:$D$33,0),MATCH($A$20,$E$23:$J$23,0)))/250,0) -> 0.036 | Q8: =IFERROR((SUMIF($B$9:$F$9,$M8,$B$10:$F$10)*INDEX($E$24:$J$33,MATCH(Q$3,$D$24:$D$33,0),MATCH($A$10,$E$23:$J$23,0))+SUMIF($B$11:$F$11,$M8,$B$12:$F$12)*INDEX($E$24:$J$33,MATCH(Q$3,$D$24:$D$33,0),MATCH($A$12,$E$23:$J$23,0))+SUMIF($B$13:$F$13,$M8,$B$14:$F$14)*INDEX($E$24:$J$33,MATCH(Q$3,$D$24:$D$33,0),MATCH($A$14,$E$23:$J$23,0))+SUMIF($B$15:$F$15,$M8,$B$16:$F$16)*INDEX($E$24:$J$33,MATCH(Q$3,$D$24:$D$33,0),MATCH($A$16,$E$23:$J$23,0))+SUMIF($B$17:$F$17,$M8,$B$18:$F$18)*INDEX($E$24:$J$33,MATCH(Q$3,$D$24:$D$33,0),MATCH($A$18,$E$23:$J$23,0))+SUMIF($B$19:$F$19,$M8,$B$20:$F$20)*INDEX($E$24:$J$33,MATCH(Q$3,$D$24:$D$33,0),MATCH($A$20,$E$23:$J$23,0)))/250,0) -> 0.024 | R8: =IFERROR((SUMIF($B$9:$F$9,$M8,$B$10:$F$10)*INDEX($E$24:$J$33,MATCH(R$3,$D$24:$D$33,0),MATCH($A$10,$E$23:$J$23,0))+SUMIF($B$11:$F$11,$M8,$B$12:$F$12)*INDEX($E$24:$J$33,MATCH(R$3,$D$24:$D$33,0),MATCH($A$12,$E$23:$J$23,0))+SUMIF($B$13:$F$13,$M8,$B$14:$F$14)*INDEX($E$24:$J$33,MATCH(R$3,$D$24:$D$33,0),MATCH($A$14,$E$23:$J$23,0))+SUMIF($B$15:$F$15,$M8,$B$16:$F$16)*INDEX($E$24:$J$33,MATCH(R$3,$D$24:$D$33,0),MATCH($A$16,$E$23:$J$23,0))+SUMIF($B$17:$F$17,$M8,$B$18:$F$18)*INDEX($E$24:$J$33,MATCH(R$3,$D$24:$D$33,0),MATCH($A$18,$E$23:$J$23,0))+SUMIF($B$19:$F$19,$M8,$B$20:$F$20)*INDEX($E$24:$J$33,MATCH(R$3,$D$24:$D$33,0),MATCH($A$20,$E$23:$J$23,0)))/250,0) -> 0.018 | S8: =IFERROR((SUMIF($B$9:$F$9,$M8,$B$10:$F$10)*INDEX($E$24:$J$33,MATCH(S$3,$D$24:$D$33,0),MATCH($A$10,$E$23:$J$23,0))+SUMIF($B$11:$F$11,$M8,$B$12:$F$12)*INDEX($E$24:$J$33,MATCH(S$3,$D$24:$D$33,0),MATCH($A$12,$E$23:$J$23,0))+SUMIF($B$13:$F$13,$M8,$B$14:$F$14)*INDEX($E$24:$J$33,MATCH(S$3,$D$24:$D$33,0),MATCH($A$14,$E$23:$J$23,0))+SUMIF($B$15:$F$15,$M8,$B$16:$F$16)*INDEX($E$24:$J$33,MATCH(S$3,$D$24:$D$33,0),MATCH($A$16,$E$23:$J$23,0))+SUMIF($B$17:$F$17,$M8,$B$18:$F$18)*INDEX($E$24:$J$33,MATCH(S$3,$D$24:$D$33,0),MATCH($A$18,$E$23:$J$23,0))+SUMIF($B$19:$F$19,$M8,$B$20:$F$20)*INDEX($E$24:$J$33,MATCH(S$3,$D$24:$D$33,0),MATCH($A$20,$E$23:$J$23,0)))/250,0) -> 0.012 | T8: =IFERROR((SUMIF($B$9:$F$9,$M8,$B$10:$F$10)*INDEX($E$24:$J$33,MATCH(T$3,$D$24:$D$33,0),MATCH($A$10,$E$23:$J$23,0))+SUMIF($B$11:$F$11,$M8,$B$12:$F$12)*INDEX($E$24:$J$33,MATCH(T$3,$D$24:$D$33,0),MATCH($A$12,$E$23:$J$23,0))+SUMIF($B$13:$F$13,$M8,$B$14:$F$14)*INDEX($E$24:$J$33,MATCH(T$3,$D$24:$D$33,0),MATCH($A$14,$E$23:$J$23,0))+SUMIF($B$15:$F$15,$M8,$B$16:$F$16)*INDEX($E$24:$J$33,MATCH(T$3,$D$24:$D$33,0),MATCH($A$16,$E$23:$J$23,0))+SUMIF($B$17:$F$17,$M8,$B$18:$F$18)*INDEX($E$24:$J$33,MATCH(T$3,$D$24:$D$33,0),MATCH($A$18,$E$23:$J$23,0))+SUMIF($B$19:$F$19,$M8,$B$20:$F$20)*INDEX($E$24:$J$33,MATCH(T$3,$D$24:$D$33,0),MATCH($A$20,$E$23:$J$23,0)))/250,0) -> 0.006 | U8: =IFERROR((SUMIF($B$9:$F$9,$M8,$B$10:$F$10)*INDEX($E$24:$J$33,MATCH(U$3,$D$24:$D$33,0),MATCH($A$10,$E$23:$J$23,0))+SUMIF($B$11:$F$11,$M8,$B$12:$F$12)*INDEX($E$24:$J$33,MATCH(U$3,$D$24:$D$33,0),MATCH($A$12,$E$23:$J$23,0))+SUMIF($B$13:$F$13,$M8,$B$14:$F$14)*INDEX($E$24:$J$33,MATCH(U$3,$D$24:$D$33,0),MATCH($A$14,$E$23:$J$23,0))+SUMIF($B$15:$F$15,$M8,$B$16:$F$16)*INDEX($E$24:$J$33,MATCH(U$3,$D$24:$D$33,0),MATCH($A$16,$E$23:$J$23,0))+SUMIF($B$17:$F$17,$M8,$B$18:$F$18)*INDEX($E$24:$J$33,MATCH(U$3,$D$24:$D$33,0),MATCH($A$18,$E$23:$J$23,0))+SUMIF($B$19:$F$19,$M8,$B$20:$F$20)*INDEX($E$24:$J$33,MATCH(U$3,$D$24:$D$33,0),MATCH($A$20,$E$23:$J$23,0)))/250,0) -> 0.012 | ... W8: =IFERROR((SUMIF($B$9:$F$9,$M8,$B$10:$F$10)*INDEX($E$24:$J$33,MATCH(W$3,$D$24:$D$33,0),MATCH($A$10,$E$23:$J$23,0))+SUMIF($B$11:$F$11,$M8,$B$12:$F$12)*INDEX($E$24:$J$33,MATCH(W$3,$D$24:$D$33,0),MATCH($A$12,$E$23:$J$23,0))+SUMIF($B$13:$F$13,$M8,$B$14:$F$14)*INDEX($E$24:$J$33,MATCH(W$3,$D$24:$D$33,0),MATCH($A$14,$E$23:$J$23,0))+SUMIF($B$15:$F$15,$M8,$B$16:$F$16)*INDEX($E$24:$J$33,MATCH(W$3,$D$24:$D$33,0),MATCH($A$16,$E$23:$J$23,0))+SUMIF($B$17:$F$17,$M8,$B$18:$F$18)*INDEX($E$24:$J$33,MATCH(W$3,$D$24:$D$33,0),MATCH($A$18,$E$23:$J$23,0))+SUMIF($B$19:$F$19,$M8,$B$20:$F$20)*INDEX($E$24:$J$33,MATCH(W$3,$D$24:$D$33,0),MATCH($A$20,$E$23:$J$23,0)))/250,0) -> 0.006 | Y8: Hazard Icon | Z8: EDEN HAZARD | AA8: 175 | AB8: 66 | AC8: =ROUND((AB8+AA8-100)/2,0) -> 71 | AD8: =AC8-AB8 -> 5 | AE8: Wikidata P2048 và hồ sơ CLB/giải đấu; có thể hiệu chỉnh
B9: FIN | C9: LSH | D9: POS | E9: HEA | F9: CRO | G9: ovr | M9: =$A29 -> SPA | N9: =IFERROR((SUMIF($B$9:$F$9,$M9,$B$10:$F$10)*INDEX($E$24:$J$33,MATCH(N$3,$D$24:$D$33,0),MATCH($A$10,$E$23:$J$23,0))+SUMIF($B$11:$F$11,$M9,$B$12:$F$12)*INDEX($E$24:$J$33,MATCH(N$3,$D$24:$D$33,0),MATCH($A$12,$E$23:$J$23,0))+SUMIF($B$13:$F$13,$M9,$B$14:$F$14)*INDEX($E$24:$J$33,MATCH(N$3,$D$24:$D$33,0),MATCH($A$14,$E$23:$J$23,0))+SUMIF($B$15:$F$15,$M9,$B$16:$F$16)*INDEX($E$24:$J$33,MATCH(N$3,$D$24:$D$33,0),MATCH($A$16,$E$23:$J$23,0))+SUMIF($B$17:$F$17,$M9,$B$18:$F$18)*INDEX($E$24:$J$33,MATCH(N$3,$D$24:$D$33,0),MATCH($A$18,$E$23:$J$23,0))+SUMIF($B$19:$F$19,$M9,$B$20:$F$20)*INDEX($E$24:$J$33,MATCH(N$3,$D$24:$D$33,0),MATCH($A$20,$E$23:$J$23,0)))/250,0) -> 0.048 | O9: =IFERROR((SUMIF($B$9:$F$9,$M9,$B$10:$F$10)*INDEX($E$24:$J$33,MATCH(O$3,$D$24:$D$33,0),MATCH($A$10,$E$23:$J$23,0))+SUMIF($B$11:$F$11,$M9,$B$12:$F$12)*INDEX($E$24:$J$33,MATCH(O$3,$D$24:$D$33,0),MATCH($A$12,$E$23:$J$23,0))+SUMIF($B$13:$F$13,$M9,$B$14:$F$14)*INDEX($E$24:$J$33,MATCH(O$3,$D$24:$D$33,0),MATCH($A$14,$E$23:$J$23,0))+SUMIF($B$15:$F$15,$M9,$B$16:$F$16)*INDEX($E$24:$J$33,MATCH(O$3,$D$24:$D$33,0),MATCH($A$16,$E$23:$J$23,0))+SUMIF($B$17:$F$17,$M9,$B$18:$F$18)*INDEX($E$24:$J$33,MATCH(O$3,$D$24:$D$33,0),MATCH($A$18,$E$23:$J$23,0))+SUMIF($B$19:$F$19,$M9,$B$20:$F$20)*INDEX($E$24:$J$33,MATCH(O$3,$D$24:$D$33,0),MATCH($A$20,$E$23:$J$23,0)))/250,0) -> 0.064 | P9: =IFERROR((SUMIF($B$9:$F$9,$M9,$B$10:$F$10)*INDEX($E$24:$J$33,MATCH(P$3,$D$24:$D$33,0),MATCH($A$10,$E$23:$J$23,0))+SUMIF($B$11:$F$11,$M9,$B$12:$F$12)*INDEX($E$24:$J$33,MATCH(P$3,$D$24:$D$33,0),MATCH($A$12,$E$23:$J$23,0))+SUMIF($B$13:$F$13,$M9,$B$14:$F$14)*INDEX($E$24:$J$33,MATCH(P$3,$D$24:$D$33,0),MATCH($A$14,$E$23:$J$23,0))+SUMIF($B$15:$F$15,$M9,$B$16:$F$16)*INDEX($E$24:$J$33,MATCH(P$3,$D$24:$D$33,0),MATCH($A$16,$E$23:$J$23,0))+SUMIF($B$17:$F$17,$M9,$B$18:$F$18)*INDEX($E$24:$J$33,MATCH(P$3,$D$24:$D$33,0),MATCH($A$18,$E$23:$J$23,0))+SUMIF($B$19:$F$19,$M9,$B$20:$F$20)*INDEX($E$24:$J$33,MATCH(P$3,$D$24:$D$33,0),MATCH($A$20,$E$23:$J$23,0)))/250,0) -> 0.064 | Q9: =IFERROR((SUMIF($B$9:$F$9,$M9,$B$10:$F$10)*INDEX($E$24:$J$33,MATCH(Q$3,$D$24:$D$33,0),MATCH($A$10,$E$23:$J$23,0))+SUMIF($B$11:$F$11,$M9,$B$12:$F$12)*INDEX($E$24:$J$33,MATCH(Q$3,$D$24:$D$33,0),MATCH($A$12,$E$23:$J$23,0))+SUMIF($B$13:$F$13,$M9,$B$14:$F$14)*INDEX($E$24:$J$33,MATCH(Q$3,$D$24:$D$33,0),MATCH($A$14,$E$23:$J$23,0))+SUMIF($B$15:$F$15,$M9,$B$16:$F$16)*INDEX($E$24:$J$33,MATCH(Q$3,$D$24:$D$33,0),MATCH($A$16,$E$23:$J$23,0))+SUMIF($B$17:$F$17,$M9,$B$18:$F$18)*INDEX($E$24:$J$33,MATCH(Q$3,$D$24:$D$33,0),MATCH($A$18,$E$23:$J$23,0))+SUMIF($B$19:$F$19,$M9,$B$20:$F$20)*INDEX($E$24:$J$33,MATCH(Q$3,$D$24:$D$33,0),MATCH($A$20,$E$23:$J$23,0)))/250,0) -> 0.112 | R9: =IFERROR((SUMIF($B$9:$F$9,$M9,$B$10:$F$10)*INDEX($E$24:$J$33,MATCH(R$3,$D$24:$D$33,0),MATCH($A$10,$E$23:$J$23,0))+SUMIF($B$11:$F$11,$M9,$B$12:$F$12)*INDEX($E$24:$J$33,MATCH(R$3,$D$24:$D$33,0),MATCH($A$12,$E$23:$J$23,0))+SUMIF($B$13:$F$13,$M9,$B$14:$F$14)*INDEX($E$24:$J$33,MATCH(R$3,$D$24:$D$33,0),MATCH($A$14,$E$23:$J$23,0))+SUMIF($B$15:$F$15,$M9,$B$16:$F$16)*INDEX($E$24:$J$33,MATCH(R$3,$D$24:$D$33,0),MATCH($A$16,$E$23:$J$23,0))+SUMIF($B$17:$F$17,$M9,$B$18:$F$18)*INDEX($E$24:$J$33,MATCH(R$3,$D$24:$D$33,0),MATCH($A$18,$E$23:$J$23,0))+SUMIF($B$19:$F$19,$M9,$B$20:$F$20)*INDEX($E$24:$J$33,MATCH(R$3,$D$24:$D$33,0),MATCH($A$20,$E$23:$J$23,0)))/250,0) -> 0.064 | S9: =IFERROR((SUMIF($B$9:$F$9,$M9,$B$10:$F$10)*INDEX($E$24:$J$33,MATCH(S$3,$D$24:$D$33,0),MATCH($A$10,$E$23:$J$23,0))+SUMIF($B$11:$F$11,$M9,$B$12:$F$12)*INDEX($E$24:$J$33,MATCH(S$3,$D$24:$D$33,0),MATCH($A$12,$E$23:$J$23,0))+SUMIF($B$13:$F$13,$M9,$B$14:$F$14)*INDEX($E$24:$J$33,MATCH(S$3,$D$24:$D$33,0),MATCH($A$14,$E$23:$J$23,0))+SUMIF($B$15:$F$15,$M9,$B$16:$F$16)*INDEX($E$24:$J$33,MATCH(S$3,$D$24:$D$33,0),MATCH($A$16,$E$23:$J$23,0))+SUMIF($B$17:$F$17,$M9,$B$18:$F$18)*INDEX($E$24:$J$33,MATCH(S$3,$D$24:$D$33,0),MATCH($A$18,$E$23:$J$23,0))+SUMIF($B$19:$F$19,$M9,$B$20:$F$20)*INDEX($E$24:$J$33,MATCH(S$3,$D$24:$D$33,0),MATCH($A$20,$E$23:$J$23,0)))/250,0) -> 0.128 | T9: =IFERROR((SUMIF($B$9:$F$9,$M9,$B$10:$F$10)*INDEX($E$24:$J$33,MATCH(T$3,$D$24:$D$33,0),MATCH($A$10,$E$23:$J$23,0))+SUMIF($B$11:$F$11,$M9,$B$12:$F$12)*INDEX($E$24:$J$33,MATCH(T$3,$D$24:$D$33,0),MATCH($A$12,$E$23:$J$23,0))+SUMIF($B$13:$F$13,$M9,$B$14:$F$14)*INDEX($E$24:$J$33,MATCH(T$3,$D$24:$D$33,0),MATCH($A$14,$E$23:$J$23,0))+SUMIF($B$15:$F$15,$M9,$B$16:$F$16)*INDEX($E$24:$J$33,MATCH(T$3,$D$24:$D$33,0),MATCH($A$16,$E$23:$J$23,0))+SUMIF($B$17:$F$17,$M9,$B$18:$F$18)*INDEX($E$24:$J$33,MATCH(T$3,$D$24:$D$33,0),MATCH($A$18,$E$23:$J$23,0))+SUMIF($B$19:$F$19,$M9,$B$20:$F$20)*INDEX($E$24:$J$33,MATCH(T$3,$D$24:$D$33,0),MATCH($A$20,$E$23:$J$23,0)))/250,0) -> 0.112 | U9: =IFERROR((SUMIF($B$9:$F$9,$M9,$B$10:$F$10)*INDEX($E$24:$J$33,MATCH(U$3,$D$24:$D$33,0),MATCH($A$10,$E$23:$J$23,0))+SUMIF($B$11:$F$11,$M9,$B$12:$F$12)*INDEX($E$24:$J$33,MATCH(U$3,$D$24:$D$33,0),MATCH($A$12,$E$23:$J$23,0))+SUMIF($B$13:$F$13,$M9,$B$14:$F$14)*INDEX($E$24:$J$33,MATCH(U$3,$D$24:$D$33,0),MATCH($A$14,$E$23:$J$23,0))+SUMIF($B$15:$F$15,$M9,$B$16:$F$16)*INDEX($E$24:$J$33,MATCH(U$3,$D$24:$D$33,0),MATCH($A$16,$E$23:$J$23,0))+SUMIF($B$17:$F$17,$M9,$B$18:$F$18)*INDEX($E$24:$J$33,MATCH(U$3,$D$24:$D$33,0),MATCH($A$18,$E$23:$J$23,0))+SUMIF($B$19:$F$19,$M9,$B$20:$F$20)*INDEX($E$24:$J$33,MATCH(U$3,$D$24:$D$33,0),MATCH($A$20,$E$23:$J$23,0)))/250,0) -> 0.08 | ... W9: =IFERROR((SUMIF($B$9:$F$9,$M9,$B$10:$F$10)*INDEX($E$24:$J$33,MATCH(W$3,$D$24:$D$33,0),MATCH($A$10,$E$23:$J$23,0))+SUMIF($B$11:$F$11,$M9,$B$12:$F$12)*INDEX($E$24:$J$33,MATCH(W$3,$D$24:$D$33,0),MATCH($A$12,$E$23:$J$23,0))+SUMIF($B$13:$F$13,$M9,$B$14:$F$14)*INDEX($E$24:$J$33,MATCH(W$3,$D$24:$D$33,0),MATCH($A$14,$E$23:$J$23,0))+SUMIF($B$15:$F$15,$M9,$B$16:$F$16)*INDEX($E$24:$J$33,MATCH(W$3,$D$24:$D$33,0),MATCH($A$16,$E$23:$J$23,0))+SUMIF($B$17:$F$17,$M9,$B$18:$F$18)*INDEX($E$24:$J$33,MATCH(W$3,$D$24:$D$33,0),MATCH($A$18,$E$23:$J$23,0))+SUMIF($B$19:$F$19,$M9,$B$20:$F$20)*INDEX($E$24:$J$33,MATCH(W$3,$D$24:$D$33,0),MATCH($A$20,$E$23:$J$23,0)))/250,0) -> 0.064 | Y9: Kane | Z9: HARRY KANE | AA9: 188 | AB9: 88 | AC9: =ROUND((AB9+AA9-100)/2,0) -> 88 | AD9: =AC9-AB9 -> 0 | AE9: Wikidata P2048 và hồ sơ CLB/giải đấu; có thể hiệu chỉnh
A10: ATK | B10: 4 | C10: 1 | D10: 2 | E10: 1.5 | F10: 1.5 | G10: =A11 / 10 -> 88.9 | H10: =ROUND(G10,0) -> 89 | M10: =$A30 -> LPA | N10: =IFERROR((SUMIF($B$9:$F$9,$M10,$B$10:$F$10)*INDEX($E$24:$J$33,MATCH(N$3,$D$24:$D$33,0),MATCH($A$10,$E$23:$J$23,0))+SUMIF($B$11:$F$11,$M10,$B$12:$F$12)*INDEX($E$24:$J$33,MATCH(N$3,$D$24:$D$33,0),MATCH($A$12,$E$23:$J$23,0))+SUMIF($B$13:$F$13,$M10,$B$14:$F$14)*INDEX($E$24:$J$33,MATCH(N$3,$D$24:$D$33,0),MATCH($A$14,$E$23:$J$23,0))+SUMIF($B$15:$F$15,$M10,$B$16:$F$16)*INDEX($E$24:$J$33,MATCH(N$3,$D$24:$D$33,0),MATCH($A$16,$E$23:$J$23,0))+SUMIF($B$17:$F$17,$M10,$B$18:$F$18)*INDEX($E$24:$J$33,MATCH(N$3,$D$24:$D$33,0),MATCH($A$18,$E$23:$J$23,0))+SUMIF($B$19:$F$19,$M10,$B$20:$F$20)*INDEX($E$24:$J$33,MATCH(N$3,$D$24:$D$33,0),MATCH($A$20,$E$23:$J$23,0)))/250,0) -> 0.024 | O10: =IFERROR((SUMIF($B$9:$F$9,$M10,$B$10:$F$10)*INDEX($E$24:$J$33,MATCH(O$3,$D$24:$D$33,0),MATCH($A$10,$E$23:$J$23,0))+SUMIF($B$11:$F$11,$M10,$B$12:$F$12)*INDEX($E$24:$J$33,MATCH(O$3,$D$24:$D$33,0),MATCH($A$12,$E$23:$J$23,0))+SUMIF($B$13:$F$13,$M10,$B$14:$F$14)*INDEX($E$24:$J$33,MATCH(O$3,$D$24:$D$33,0),MATCH($A$14,$E$23:$J$23,0))+SUMIF($B$15:$F$15,$M10,$B$16:$F$16)*INDEX($E$24:$J$33,MATCH(O$3,$D$24:$D$33,0),MATCH($A$16,$E$23:$J$23,0))+SUMIF($B$17:$F$17,$M10,$B$18:$F$18)*INDEX($E$24:$J$33,MATCH(O$3,$D$24:$D$33,0),MATCH($A$18,$E$23:$J$23,0))+SUMIF($B$19:$F$19,$M10,$B$20:$F$20)*INDEX($E$24:$J$33,MATCH(O$3,$D$24:$D$33,0),MATCH($A$20,$E$23:$J$23,0)))/250,0) -> 0.032 | P10: =IFERROR((SUMIF($B$9:$F$9,$M10,$B$10:$F$10)*INDEX($E$24:$J$33,MATCH(P$3,$D$24:$D$33,0),MATCH($A$10,$E$23:$J$23,0))+SUMIF($B$11:$F$11,$M10,$B$12:$F$12)*INDEX($E$24:$J$33,MATCH(P$3,$D$24:$D$33,0),MATCH($A$12,$E$23:$J$23,0))+SUMIF($B$13:$F$13,$M10,$B$14:$F$14)*INDEX($E$24:$J$33,MATCH(P$3,$D$24:$D$33,0),MATCH($A$14,$E$23:$J$23,0))+SUMIF($B$15:$F$15,$M10,$B$16:$F$16)*INDEX($E$24:$J$33,MATCH(P$3,$D$24:$D$33,0),MATCH($A$16,$E$23:$J$23,0))+SUMIF($B$17:$F$17,$M10,$B$18:$F$18)*INDEX($E$24:$J$33,MATCH(P$3,$D$24:$D$33,0),MATCH($A$18,$E$23:$J$23,0))+SUMIF($B$19:$F$19,$M10,$B$20:$F$20)*INDEX($E$24:$J$33,MATCH(P$3,$D$24:$D$33,0),MATCH($A$20,$E$23:$J$23,0)))/250,0) -> 0.032 | Q10: =IFERROR((SUMIF($B$9:$F$9,$M10,$B$10:$F$10)*INDEX($E$24:$J$33,MATCH(Q$3,$D$24:$D$33,0),MATCH($A$10,$E$23:$J$23,0))+SUMIF($B$11:$F$11,$M10,$B$12:$F$12)*INDEX($E$24:$J$33,MATCH(Q$3,$D$24:$D$33,0),MATCH($A$12,$E$23:$J$23,0))+SUMIF($B$13:$F$13,$M10,$B$14:$F$14)*INDEX($E$24:$J$33,MATCH(Q$3,$D$24:$D$33,0),MATCH($A$14,$E$23:$J$23,0))+SUMIF($B$15:$F$15,$M10,$B$16:$F$16)*INDEX($E$24:$J$33,MATCH(Q$3,$D$24:$D$33,0),MATCH($A$16,$E$23:$J$23,0))+SUMIF($B$17:$F$17,$M10,$B$18:$F$18)*INDEX($E$24:$J$33,MATCH(Q$3,$D$24:$D$33,0),MATCH($A$18,$E$23:$J$23,0))+SUMIF($B$19:$F$19,$M10,$B$20:$F$20)*INDEX($E$24:$J$33,MATCH(Q$3,$D$24:$D$33,0),MATCH($A$20,$E$23:$J$23,0)))/250,0) -> 0.056 | R10: =IFERROR((SUMIF($B$9:$F$9,$M10,$B$10:$F$10)*INDEX($E$24:$J$33,MATCH(R$3,$D$24:$D$33,0),MATCH($A$10,$E$23:$J$23,0))+SUMIF($B$11:$F$11,$M10,$B$12:$F$12)*INDEX($E$24:$J$33,MATCH(R$3,$D$24:$D$33,0),MATCH($A$12,$E$23:$J$23,0))+SUMIF($B$13:$F$13,$M10,$B$14:$F$14)*INDEX($E$24:$J$33,MATCH(R$3,$D$24:$D$33,0),MATCH($A$14,$E$23:$J$23,0))+SUMIF($B$15:$F$15,$M10,$B$16:$F$16)*INDEX($E$24:$J$33,MATCH(R$3,$D$24:$D$33,0),MATCH($A$16,$E$23:$J$23,0))+SUMIF($B$17:$F$17,$M10,$B$18:$F$18)*INDEX($E$24:$J$33,MATCH(R$3,$D$24:$D$33,0),MATCH($A$18,$E$23:$J$23,0))+SUMIF($B$19:$F$19,$M10,$B$20:$F$20)*INDEX($E$24:$J$33,MATCH(R$3,$D$24:$D$33,0),MATCH($A$20,$E$23:$J$23,0)))/250,0) -> 0.032 | S10: =IFERROR((SUMIF($B$9:$F$9,$M10,$B$10:$F$10)*INDEX($E$24:$J$33,MATCH(S$3,$D$24:$D$33,0),MATCH($A$10,$E$23:$J$23,0))+SUMIF($B$11:$F$11,$M10,$B$12:$F$12)*INDEX($E$24:$J$33,MATCH(S$3,$D$24:$D$33,0),MATCH($A$12,$E$23:$J$23,0))+SUMIF($B$13:$F$13,$M10,$B$14:$F$14)*INDEX($E$24:$J$33,MATCH(S$3,$D$24:$D$33,0),MATCH($A$14,$E$23:$J$23,0))+SUMIF($B$15:$F$15,$M10,$B$16:$F$16)*INDEX($E$24:$J$33,MATCH(S$3,$D$24:$D$33,0),MATCH($A$16,$E$23:$J$23,0))+SUMIF($B$17:$F$17,$M10,$B$18:$F$18)*INDEX($E$24:$J$33,MATCH(S$3,$D$24:$D$33,0),MATCH($A$18,$E$23:$J$23,0))+SUMIF($B$19:$F$19,$M10,$B$20:$F$20)*INDEX($E$24:$J$33,MATCH(S$3,$D$24:$D$33,0),MATCH($A$20,$E$23:$J$23,0)))/250,0) -> 0.064 | T10: =IFERROR((SUMIF($B$9:$F$9,$M10,$B$10:$F$10)*INDEX($E$24:$J$33,MATCH(T$3,$D$24:$D$33,0),MATCH($A$10,$E$23:$J$23,0))+SUMIF($B$11:$F$11,$M10,$B$12:$F$12)*INDEX($E$24:$J$33,MATCH(T$3,$D$24:$D$33,0),MATCH($A$12,$E$23:$J$23,0))+SUMIF($B$13:$F$13,$M10,$B$14:$F$14)*INDEX($E$24:$J$33,MATCH(T$3,$D$24:$D$33,0),MATCH($A$14,$E$23:$J$23,0))+SUMIF($B$15:$F$15,$M10,$B$16:$F$16)*INDEX($E$24:$J$33,MATCH(T$3,$D$24:$D$33,0),MATCH($A$16,$E$23:$J$23,0))+SUMIF($B$17:$F$17,$M10,$B$18:$F$18)*INDEX($E$24:$J$33,MATCH(T$3,$D$24:$D$33,0),MATCH($A$18,$E$23:$J$23,0))+SUMIF($B$19:$F$19,$M10,$B$20:$F$20)*INDEX($E$24:$J$33,MATCH(T$3,$D$24:$D$33,0),MATCH($A$20,$E$23:$J$23,0)))/250,0) -> 0.056 | U10: =IFERROR((SUMIF($B$9:$F$9,$M10,$B$10:$F$10)*INDEX($E$24:$J$33,MATCH(U$3,$D$24:$D$33,0),MATCH($A$10,$E$23:$J$23,0))+SUMIF($B$11:$F$11,$M10,$B$12:$F$12)*INDEX($E$24:$J$33,MATCH(U$3,$D$24:$D$33,0),MATCH($A$12,$E$23:$J$23,0))+SUMIF($B$13:$F$13,$M10,$B$14:$F$14)*INDEX($E$24:$J$33,MATCH(U$3,$D$24:$D$33,0),MATCH($A$14,$E$23:$J$23,0))+SUMIF($B$15:$F$15,$M10,$B$16:$F$16)*INDEX($E$24:$J$33,MATCH(U$3,$D$24:$D$33,0),MATCH($A$16,$E$23:$J$23,0))+SUMIF($B$17:$F$17,$M10,$B$18:$F$18)*INDEX($E$24:$J$33,MATCH(U$3,$D$24:$D$33,0),MATCH($A$18,$E$23:$J$23,0))+SUMIF($B$19:$F$19,$M10,$B$20:$F$20)*INDEX($E$24:$J$33,MATCH(U$3,$D$24:$D$33,0),MATCH($A$20,$E$23:$J$23,0)))/250,0) -> 0.04 | ... W10: =IFERROR((SUMIF($B$9:$F$9,$M10,$B$10:$F$10)*INDEX($E$24:$J$33,MATCH(W$3,$D$24:$D$33,0),MATCH($A$10,$E$23:$J$23,0))+SUMIF($B$11:$F$11,$M10,$B$12:$F$12)*INDEX($E$24:$J$33,MATCH(W$3,$D$24:$D$33,0),MATCH($A$12,$E$23:$J$23,0))+SUMIF($B$13:$F$13,$M10,$B$14:$F$14)*INDEX($E$24:$J$33,MATCH(W$3,$D$24:$D$33,0),MATCH($A$14,$E$23:$J$23,0))+SUMIF($B$15:$F$15,$M10,$B$16:$F$16)*INDEX($E$24:$J$33,MATCH(W$3,$D$24:$D$33,0),MATCH($A$16,$E$23:$J$23,0))+SUMIF($B$17:$F$17,$M10,$B$18:$F$18)*INDEX($E$24:$J$33,MATCH(W$3,$D$24:$D$33,0),MATCH($A$18,$E$23:$J$23,0))+SUMIF($B$19:$F$19,$M10,$B$20:$F$20)*INDEX($E$24:$J$33,MATCH(W$3,$D$24:$D$33,0),MATCH($A$20,$E$23:$J$23,0)))/250,0) -> 0.032 | Y10: Ibrahimovic Icon | Z10: ZLATAN IBRAHIMOVIĆ | AA10: 195 | AB10: 90 | AC10: =ROUND((AB10+AA10-100)/2,0) -> 93 | AD10: =AC10-AB10 -> 3 | AE10: Wikidata P2048 và hồ sơ CLB/giải đấu; có thể hiệu chỉnh
A11: =B24 * B10 + B25 * C10 + B26 * D10 + B27 * E10 + B28 * F10 -> 889 | B11: SPA | C11: LPA | D11: VIS | E11: CON | M11: =$A31 -> VIS | N11: =IFERROR((SUMIF($B$9:$F$9,$M11,$B$10:$F$10)*INDEX($E$24:$J$33,MATCH(N$3,$D$24:$D$33,0),MATCH($A$10,$E$23:$J$23,0))+SUMIF($B$11:$F$11,$M11,$B$12:$F$12)*INDEX($E$24:$J$33,MATCH(N$3,$D$24:$D$33,0),MATCH($A$12,$E$23:$J$23,0))+SUMIF($B$13:$F$13,$M11,$B$14:$F$14)*INDEX($E$24:$J$33,MATCH(N$3,$D$24:$D$33,0),MATCH($A$14,$E$23:$J$23,0))+SUMIF($B$15:$F$15,$M11,$B$16:$F$16)*INDEX($E$24:$J$33,MATCH(N$3,$D$24:$D$33,0),MATCH($A$16,$E$23:$J$23,0))+SUMIF($B$17:$F$17,$M11,$B$18:$F$18)*INDEX($E$24:$J$33,MATCH(N$3,$D$24:$D$33,0),MATCH($A$18,$E$23:$J$23,0))+SUMIF($B$19:$F$19,$M11,$B$20:$F$20)*INDEX($E$24:$J$33,MATCH(N$3,$D$24:$D$33,0),MATCH($A$20,$E$23:$J$23,0)))/250,0) -> 0.056 | O11: =IFERROR((SUMIF($B$9:$F$9,$M11,$B$10:$F$10)*INDEX($E$24:$J$33,MATCH(O$3,$D$24:$D$33,0),MATCH($A$10,$E$23:$J$23,0))+SUMIF($B$11:$F$11,$M11,$B$12:$F$12)*INDEX($E$24:$J$33,MATCH(O$3,$D$24:$D$33,0),MATCH($A$12,$E$23:$J$23,0))+SUMIF($B$13:$F$13,$M11,$B$14:$F$14)*INDEX($E$24:$J$33,MATCH(O$3,$D$24:$D$33,0),MATCH($A$14,$E$23:$J$23,0))+SUMIF($B$15:$F$15,$M11,$B$16:$F$16)*INDEX($E$24:$J$33,MATCH(O$3,$D$24:$D$33,0),MATCH($A$16,$E$23:$J$23,0))+SUMIF($B$17:$F$17,$M11,$B$18:$F$18)*INDEX($E$24:$J$33,MATCH(O$3,$D$24:$D$33,0),MATCH($A$18,$E$23:$J$23,0))+SUMIF($B$19:$F$19,$M11,$B$20:$F$20)*INDEX($E$24:$J$33,MATCH(O$3,$D$24:$D$33,0),MATCH($A$20,$E$23:$J$23,0)))/250,0) -> 0.064 | P11: =IFERROR((SUMIF($B$9:$F$9,$M11,$B$10:$F$10)*INDEX($E$24:$J$33,MATCH(P$3,$D$24:$D$33,0),MATCH($A$10,$E$23:$J$23,0))+SUMIF($B$11:$F$11,$M11,$B$12:$F$12)*INDEX($E$24:$J$33,MATCH(P$3,$D$24:$D$33,0),MATCH($A$12,$E$23:$J$23,0))+SUMIF($B$13:$F$13,$M11,$B$14:$F$14)*INDEX($E$24:$J$33,MATCH(P$3,$D$24:$D$33,0),MATCH($A$14,$E$23:$J$23,0))+SUMIF($B$15:$F$15,$M11,$B$16:$F$16)*INDEX($E$24:$J$33,MATCH(P$3,$D$24:$D$33,0),MATCH($A$16,$E$23:$J$23,0))+SUMIF($B$17:$F$17,$M11,$B$18:$F$18)*INDEX($E$24:$J$33,MATCH(P$3,$D$24:$D$33,0),MATCH($A$18,$E$23:$J$23,0))+SUMIF($B$19:$F$19,$M11,$B$20:$F$20)*INDEX($E$24:$J$33,MATCH(P$3,$D$24:$D$33,0),MATCH($A$20,$E$23:$J$23,0)))/250,0) -> 0.068 | Q11: =IFERROR((SUMIF($B$9:$F$9,$M11,$B$10:$F$10)*INDEX($E$24:$J$33,MATCH(Q$3,$D$24:$D$33,0),MATCH($A$10,$E$23:$J$23,0))+SUMIF($B$11:$F$11,$M11,$B$12:$F$12)*INDEX($E$24:$J$33,MATCH(Q$3,$D$24:$D$33,0),MATCH($A$12,$E$23:$J$23,0))+SUMIF($B$13:$F$13,$M11,$B$14:$F$14)*INDEX($E$24:$J$33,MATCH(Q$3,$D$24:$D$33,0),MATCH($A$14,$E$23:$J$23,0))+SUMIF($B$15:$F$15,$M11,$B$16:$F$16)*INDEX($E$24:$J$33,MATCH(Q$3,$D$24:$D$33,0),MATCH($A$16,$E$23:$J$23,0))+SUMIF($B$17:$F$17,$M11,$B$18:$F$18)*INDEX($E$24:$J$33,MATCH(Q$3,$D$24:$D$33,0),MATCH($A$18,$E$23:$J$23,0))+SUMIF($B$19:$F$19,$M11,$B$20:$F$20)*INDEX($E$24:$J$33,MATCH(Q$3,$D$24:$D$33,0),MATCH($A$20,$E$23:$J$23,0)))/250,0) -> 0.076 | R11: =IFERROR((SUMIF($B$9:$F$9,$M11,$B$10:$F$10)*INDEX($E$24:$J$33,MATCH(R$3,$D$24:$D$33,0),MATCH($A$10,$E$23:$J$23,0))+SUMIF($B$11:$F$11,$M11,$B$12:$F$12)*INDEX($E$24:$J$33,MATCH(R$3,$D$24:$D$33,0),MATCH($A$12,$E$23:$J$23,0))+SUMIF($B$13:$F$13,$M11,$B$14:$F$14)*INDEX($E$24:$J$33,MATCH(R$3,$D$24:$D$33,0),MATCH($A$14,$E$23:$J$23,0))+SUMIF($B$15:$F$15,$M11,$B$16:$F$16)*INDEX($E$24:$J$33,MATCH(R$3,$D$24:$D$33,0),MATCH($A$16,$E$23:$J$23,0))+SUMIF($B$17:$F$17,$M11,$B$18:$F$18)*INDEX($E$24:$J$33,MATCH(R$3,$D$24:$D$33,0),MATCH($A$18,$E$23:$J$23,0))+SUMIF($B$19:$F$19,$M11,$B$20:$F$20)*INDEX($E$24:$J$33,MATCH(R$3,$D$24:$D$33,0),MATCH($A$20,$E$23:$J$23,0)))/250,0) -> 0.068 | S11: =IFERROR((SUMIF($B$9:$F$9,$M11,$B$10:$F$10)*INDEX($E$24:$J$33,MATCH(S$3,$D$24:$D$33,0),MATCH($A$10,$E$23:$J$23,0))+SUMIF($B$11:$F$11,$M11,$B$12:$F$12)*INDEX($E$24:$J$33,MATCH(S$3,$D$24:$D$33,0),MATCH($A$12,$E$23:$J$23,0))+SUMIF($B$13:$F$13,$M11,$B$14:$F$14)*INDEX($E$24:$J$33,MATCH(S$3,$D$24:$D$33,0),MATCH($A$14,$E$23:$J$23,0))+SUMIF($B$15:$F$15,$M11,$B$16:$F$16)*INDEX($E$24:$J$33,MATCH(S$3,$D$24:$D$33,0),MATCH($A$16,$E$23:$J$23,0))+SUMIF($B$17:$F$17,$M11,$B$18:$F$18)*INDEX($E$24:$J$33,MATCH(S$3,$D$24:$D$33,0),MATCH($A$18,$E$23:$J$23,0))+SUMIF($B$19:$F$19,$M11,$B$20:$F$20)*INDEX($E$24:$J$33,MATCH(S$3,$D$24:$D$33,0),MATCH($A$20,$E$23:$J$23,0)))/250,0) -> 0.068 | T11: =IFERROR((SUMIF($B$9:$F$9,$M11,$B$10:$F$10)*INDEX($E$24:$J$33,MATCH(T$3,$D$24:$D$33,0),MATCH($A$10,$E$23:$J$23,0))+SUMIF($B$11:$F$11,$M11,$B$12:$F$12)*INDEX($E$24:$J$33,MATCH(T$3,$D$24:$D$33,0),MATCH($A$12,$E$23:$J$23,0))+SUMIF($B$13:$F$13,$M11,$B$14:$F$14)*INDEX($E$24:$J$33,MATCH(T$3,$D$24:$D$33,0),MATCH($A$14,$E$23:$J$23,0))+SUMIF($B$15:$F$15,$M11,$B$16:$F$16)*INDEX($E$24:$J$33,MATCH(T$3,$D$24:$D$33,0),MATCH($A$16,$E$23:$J$23,0))+SUMIF($B$17:$F$17,$M11,$B$18:$F$18)*INDEX($E$24:$J$33,MATCH(T$3,$D$24:$D$33,0),MATCH($A$18,$E$23:$J$23,0))+SUMIF($B$19:$F$19,$M11,$B$20:$F$20)*INDEX($E$24:$J$33,MATCH(T$3,$D$24:$D$33,0),MATCH($A$20,$E$23:$J$23,0)))/250,0) -> 0.06 | U11: =IFERROR((SUMIF($B$9:$F$9,$M11,$B$10:$F$10)*INDEX($E$24:$J$33,MATCH(U$3,$D$24:$D$33,0),MATCH($A$10,$E$23:$J$23,0))+SUMIF($B$11:$F$11,$M11,$B$12:$F$12)*INDEX($E$24:$J$33,MATCH(U$3,$D$24:$D$33,0),MATCH($A$12,$E$23:$J$23,0))+SUMIF($B$13:$F$13,$M11,$B$14:$F$14)*INDEX($E$24:$J$33,MATCH(U$3,$D$24:$D$33,0),MATCH($A$14,$E$23:$J$23,0))+SUMIF($B$15:$F$15,$M11,$B$16:$F$16)*INDEX($E$24:$J$33,MATCH(U$3,$D$24:$D$33,0),MATCH($A$16,$E$23:$J$23,0))+SUMIF($B$17:$F$17,$M11,$B$18:$F$18)*INDEX($E$24:$J$33,MATCH(U$3,$D$24:$D$33,0),MATCH($A$18,$E$23:$J$23,0))+SUMIF($B$19:$F$19,$M11,$B$20:$F$20)*INDEX($E$24:$J$33,MATCH(U$3,$D$24:$D$33,0),MATCH($A$20,$E$23:$J$23,0)))/250,0) -> 0.064 | ... W11: =IFERROR((SUMIF($B$9:$F$9,$M11,$B$10:$F$10)*INDEX($E$24:$J$33,MATCH(W$3,$D$24:$D$33,0),MATCH($A$10,$E$23:$J$23,0))+SUMIF($B$11:$F$11,$M11,$B$12:$F$12)*INDEX($E$24:$J$33,MATCH(W$3,$D$24:$D$33,0),MATCH($A$12,$E$23:$J$23,0))+SUMIF($B$13:$F$13,$M11,$B$14:$F$14)*INDEX($E$24:$J$33,MATCH(W$3,$D$24:$D$33,0),MATCH($A$14,$E$23:$J$23,0))+SUMIF($B$15:$F$15,$M11,$B$16:$F$16)*INDEX($E$24:$J$33,MATCH(W$3,$D$24:$D$33,0),MATCH($A$16,$E$23:$J$23,0))+SUMIF($B$17:$F$17,$M11,$B$18:$F$18)*INDEX($E$24:$J$33,MATCH(W$3,$D$24:$D$33,0),MATCH($A$18,$E$23:$J$23,0))+SUMIF($B$19:$F$19,$M11,$B$20:$F$20)*INDEX($E$24:$J$33,MATCH(W$3,$D$24:$D$33,0),MATCH($A$20,$E$23:$J$23,0)))/250,0) -> 0.044 | Y11: Son Icon | Z11: SON HEUNG-MIN | AA11: 183 | AB11: 70 | AC11: =ROUND((AB11+AA11-100)/2,0) -> 77 | AD11: =AC11-AB11 -> 7 | AE11: Wikidata P2048 và hồ sơ CLB/giải đấu; có thể hiệu chỉnh
A12: DIS | B12: 4 | C12: 2 | D12: 1 | E12: 3 | G12: =A13 / 10 -> 89 | H12: =ROUND(G12,0) -> 89 | M12: =$A32 -> CON | N12: =IFERROR((SUMIF($B$9:$F$9,$M12,$B$10:$F$10)*INDEX($E$24:$J$33,MATCH(N$3,$D$24:$D$33,0),MATCH($A$10,$E$23:$J$23,0))+SUMIF($B$11:$F$11,$M12,$B$12:$F$12)*INDEX($E$24:$J$33,MATCH(N$3,$D$24:$D$33,0),MATCH($A$12,$E$23:$J$23,0))+SUMIF($B$13:$F$13,$M12,$B$14:$F$14)*INDEX($E$24:$J$33,MATCH(N$3,$D$24:$D$33,0),MATCH($A$14,$E$23:$J$23,0))+SUMIF($B$15:$F$15,$M12,$B$16:$F$16)*INDEX($E$24:$J$33,MATCH(N$3,$D$24:$D$33,0),MATCH($A$16,$E$23:$J$23,0))+SUMIF($B$17:$F$17,$M12,$B$18:$F$18)*INDEX($E$24:$J$33,MATCH(N$3,$D$24:$D$33,0),MATCH($A$18,$E$23:$J$23,0))+SUMIF($B$19:$F$19,$M12,$B$20:$F$20)*INDEX($E$24:$J$33,MATCH(N$3,$D$24:$D$33,0),MATCH($A$20,$E$23:$J$23,0)))/250,0) -> 0.056 | O12: =IFERROR((SUMIF($B$9:$F$9,$M12,$B$10:$F$10)*INDEX($E$24:$J$33,MATCH(O$3,$D$24:$D$33,0),MATCH($A$10,$E$23:$J$23,0))+SUMIF($B$11:$F$11,$M12,$B$12:$F$12)*INDEX($E$24:$J$33,MATCH(O$3,$D$24:$D$33,0),MATCH($A$12,$E$23:$J$23,0))+SUMIF($B$13:$F$13,$M12,$B$14:$F$14)*INDEX($E$24:$J$33,MATCH(O$3,$D$24:$D$33,0),MATCH($A$14,$E$23:$J$23,0))+SUMIF($B$15:$F$15,$M12,$B$16:$F$16)*INDEX($E$24:$J$33,MATCH(O$3,$D$24:$D$33,0),MATCH($A$16,$E$23:$J$23,0))+SUMIF($B$17:$F$17,$M12,$B$18:$F$18)*INDEX($E$24:$J$33,MATCH(O$3,$D$24:$D$33,0),MATCH($A$18,$E$23:$J$23,0))+SUMIF($B$19:$F$19,$M12,$B$20:$F$20)*INDEX($E$24:$J$33,MATCH(O$3,$D$24:$D$33,0),MATCH($A$20,$E$23:$J$23,0)))/250,0) -> 0.072 | P12: =IFERROR((SUMIF($B$9:$F$9,$M12,$B$10:$F$10)*INDEX($E$24:$J$33,MATCH(P$3,$D$24:$D$33,0),MATCH($A$10,$E$23:$J$23,0))+SUMIF($B$11:$F$11,$M12,$B$12:$F$12)*INDEX($E$24:$J$33,MATCH(P$3,$D$24:$D$33,0),MATCH($A$12,$E$23:$J$23,0))+SUMIF($B$13:$F$13,$M12,$B$14:$F$14)*INDEX($E$24:$J$33,MATCH(P$3,$D$24:$D$33,0),MATCH($A$14,$E$23:$J$23,0))+SUMIF($B$15:$F$15,$M12,$B$16:$F$16)*INDEX($E$24:$J$33,MATCH(P$3,$D$24:$D$33,0),MATCH($A$16,$E$23:$J$23,0))+SUMIF($B$17:$F$17,$M12,$B$18:$F$18)*INDEX($E$24:$J$33,MATCH(P$3,$D$24:$D$33,0),MATCH($A$18,$E$23:$J$23,0))+SUMIF($B$19:$F$19,$M12,$B$20:$F$20)*INDEX($E$24:$J$33,MATCH(P$3,$D$24:$D$33,0),MATCH($A$20,$E$23:$J$23,0)))/250,0) -> 0.076 | Q12: =IFERROR((SUMIF($B$9:$F$9,$M12,$B$10:$F$10)*INDEX($E$24:$J$33,MATCH(Q$3,$D$24:$D$33,0),MATCH($A$10,$E$23:$J$23,0))+SUMIF($B$11:$F$11,$M12,$B$12:$F$12)*INDEX($E$24:$J$33,MATCH(Q$3,$D$24:$D$33,0),MATCH($A$12,$E$23:$J$23,0))+SUMIF($B$13:$F$13,$M12,$B$14:$F$14)*INDEX($E$24:$J$33,MATCH(Q$3,$D$24:$D$33,0),MATCH($A$14,$E$23:$J$23,0))+SUMIF($B$15:$F$15,$M12,$B$16:$F$16)*INDEX($E$24:$J$33,MATCH(Q$3,$D$24:$D$33,0),MATCH($A$16,$E$23:$J$23,0))+SUMIF($B$17:$F$17,$M12,$B$18:$F$18)*INDEX($E$24:$J$33,MATCH(Q$3,$D$24:$D$33,0),MATCH($A$18,$E$23:$J$23,0))+SUMIF($B$19:$F$19,$M12,$B$20:$F$20)*INDEX($E$24:$J$33,MATCH(Q$3,$D$24:$D$33,0),MATCH($A$20,$E$23:$J$23,0)))/250,0) -> 0.108 | R12: =IFERROR((SUMIF($B$9:$F$9,$M12,$B$10:$F$10)*INDEX($E$24:$J$33,MATCH(R$3,$D$24:$D$33,0),MATCH($A$10,$E$23:$J$23,0))+SUMIF($B$11:$F$11,$M12,$B$12:$F$12)*INDEX($E$24:$J$33,MATCH(R$3,$D$24:$D$33,0),MATCH($A$12,$E$23:$J$23,0))+SUMIF($B$13:$F$13,$M12,$B$14:$F$14)*INDEX($E$24:$J$33,MATCH(R$3,$D$24:$D$33,0),MATCH($A$14,$E$23:$J$23,0))+SUMIF($B$15:$F$15,$M12,$B$16:$F$16)*INDEX($E$24:$J$33,MATCH(R$3,$D$24:$D$33,0),MATCH($A$16,$E$23:$J$23,0))+SUMIF($B$17:$F$17,$M12,$B$18:$F$18)*INDEX($E$24:$J$33,MATCH(R$3,$D$24:$D$33,0),MATCH($A$18,$E$23:$J$23,0))+SUMIF($B$19:$F$19,$M12,$B$20:$F$20)*INDEX($E$24:$J$33,MATCH(R$3,$D$24:$D$33,0),MATCH($A$20,$E$23:$J$23,0)))/250,0) -> 0.076 | S12: =IFERROR((SUMIF($B$9:$F$9,$M12,$B$10:$F$10)*INDEX($E$24:$J$33,MATCH(S$3,$D$24:$D$33,0),MATCH($A$10,$E$23:$J$23,0))+SUMIF($B$11:$F$11,$M12,$B$12:$F$12)*INDEX($E$24:$J$33,MATCH(S$3,$D$24:$D$33,0),MATCH($A$12,$E$23:$J$23,0))+SUMIF($B$13:$F$13,$M12,$B$14:$F$14)*INDEX($E$24:$J$33,MATCH(S$3,$D$24:$D$33,0),MATCH($A$14,$E$23:$J$23,0))+SUMIF($B$15:$F$15,$M12,$B$16:$F$16)*INDEX($E$24:$J$33,MATCH(S$3,$D$24:$D$33,0),MATCH($A$16,$E$23:$J$23,0))+SUMIF($B$17:$F$17,$M12,$B$18:$F$18)*INDEX($E$24:$J$33,MATCH(S$3,$D$24:$D$33,0),MATCH($A$18,$E$23:$J$23,0))+SUMIF($B$19:$F$19,$M12,$B$20:$F$20)*INDEX($E$24:$J$33,MATCH(S$3,$D$24:$D$33,0),MATCH($A$20,$E$23:$J$23,0)))/250,0) -> 0.108 | T12: =IFERROR((SUMIF($B$9:$F$9,$M12,$B$10:$F$10)*INDEX($E$24:$J$33,MATCH(T$3,$D$24:$D$33,0),MATCH($A$10,$E$23:$J$23,0))+SUMIF($B$11:$F$11,$M12,$B$12:$F$12)*INDEX($E$24:$J$33,MATCH(T$3,$D$24:$D$33,0),MATCH($A$12,$E$23:$J$23,0))+SUMIF($B$13:$F$13,$M12,$B$14:$F$14)*INDEX($E$24:$J$33,MATCH(T$3,$D$24:$D$33,0),MATCH($A$14,$E$23:$J$23,0))+SUMIF($B$15:$F$15,$M12,$B$16:$F$16)*INDEX($E$24:$J$33,MATCH(T$3,$D$24:$D$33,0),MATCH($A$16,$E$23:$J$23,0))+SUMIF($B$17:$F$17,$M12,$B$18:$F$18)*INDEX($E$24:$J$33,MATCH(T$3,$D$24:$D$33,0),MATCH($A$18,$E$23:$J$23,0))+SUMIF($B$19:$F$19,$M12,$B$20:$F$20)*INDEX($E$24:$J$33,MATCH(T$3,$D$24:$D$33,0),MATCH($A$20,$E$23:$J$23,0)))/250,0) -> 0.092 | U12: =IFERROR((SUMIF($B$9:$F$9,$M12,$B$10:$F$10)*INDEX($E$24:$J$33,MATCH(U$3,$D$24:$D$33,0),MATCH($A$10,$E$23:$J$23,0))+SUMIF($B$11:$F$11,$M12,$B$12:$F$12)*INDEX($E$24:$J$33,MATCH(U$3,$D$24:$D$33,0),MATCH($A$12,$E$23:$J$23,0))+SUMIF($B$13:$F$13,$M12,$B$14:$F$14)*INDEX($E$24:$J$33,MATCH(U$3,$D$24:$D$33,0),MATCH($A$14,$E$23:$J$23,0))+SUMIF($B$15:$F$15,$M12,$B$16:$F$16)*INDEX($E$24:$J$33,MATCH(U$3,$D$24:$D$33,0),MATCH($A$16,$E$23:$J$23,0))+SUMIF($B$17:$F$17,$M12,$B$18:$F$18)*INDEX($E$24:$J$33,MATCH(U$3,$D$24:$D$33,0),MATCH($A$18,$E$23:$J$23,0))+SUMIF($B$19:$F$19,$M12,$B$20:$F$20)*INDEX($E$24:$J$33,MATCH(U$3,$D$24:$D$33,0),MATCH($A$20,$E$23:$J$23,0)))/250,0) -> 0.08 | ... W12: =IFERROR((SUMIF($B$9:$F$9,$M12,$B$10:$F$10)*INDEX($E$24:$J$33,MATCH(W$3,$D$24:$D$33,0),MATCH($A$10,$E$23:$J$23,0))+SUMIF($B$11:$F$11,$M12,$B$12:$F$12)*INDEX($E$24:$J$33,MATCH(W$3,$D$24:$D$33,0),MATCH($A$12,$E$23:$J$23,0))+SUMIF($B$13:$F$13,$M12,$B$14:$F$14)*INDEX($E$24:$J$33,MATCH(W$3,$D$24:$D$33,0),MATCH($A$14,$E$23:$J$23,0))+SUMIF($B$15:$F$15,$M12,$B$16:$F$16)*INDEX($E$24:$J$33,MATCH(W$3,$D$24:$D$33,0),MATCH($A$16,$E$23:$J$23,0))+SUMIF($B$17:$F$17,$M12,$B$18:$F$18)*INDEX($E$24:$J$33,MATCH(W$3,$D$24:$D$33,0),MATCH($A$18,$E$23:$J$23,0))+SUMIF($B$19:$F$19,$M12,$B$20:$F$20)*INDEX($E$24:$J$33,MATCH(W$3,$D$24:$D$33,0),MATCH($A$20,$E$23:$J$23,0)))/250,0) -> 0.052 | Y12: Rodri | Z12: RODRI | AA12: 191 | AB12: 83 | AC12: =ROUND((AB12+AA12-100)/2,0) -> 87 | AD12: =AC12-AB12 -> 4 | AE12: Wikidata P2048 và hồ sơ CLB/giải đấu; có thể hiệu chỉnh
